Workbook

Sheet الجدول
B1: ER ADMISSION-NIGHT-🚨🌙 | C1: ER ADMISSIONS -DAY-🚨☀️ | D1: ER-clinic Day ☀️🚨 | E1: ER GENERAL-DAY-🚨☀️ | F1: ER GENERAL-NIGHT-🚨🌙 | G1: ER PT-DAY-🚨☀️ | H1: ER PT-NIGHT-🚨🌙 | I1: ER TRIAGE-DAY-🚨☀️ | J1: ER TRIAGE-NIGHT-🚨🌙 | K1: ER WARD-DAY-🚨☀️ | L1: ER WARD-NIGHT-🚨🌙 | M1: 🗡️LISTA | N1: WARD-DAY-☀️ | O1: WARD-NIGHT-🌙
A2: 2026-02-01 الأحد | B2: بلال جودة (01066199644) | C2: سلمى أبوالعلا (01124166114) | D2: دانه طارق (01012809042) | E2: استيفن مدحت منير (01200226122) | F2: عمرو وائل سرور (01023140340) | G2: مينا رومانى عبده (01212866642) | H2: سندس أحمد سيد (01156131096) | I2: كارين روماني راشد (01102663062) | J2: ملك محمد فؤاد (01001721072) | K2: محمود عبد المحسن إبراهيم (01062086612) | L2: محمد الجمل (01091463337) | M2: ---------- | N2: ---------- | O2: ---------- | P2: =HYPERLINK("#مجمع!B" & 1, "ورديات اليوم مجمعة") -> ورديات اليوم مجمعة
B3: ---------- | C3: ---------- | D3: ---------- | E3: محمد خالد محمد (01008204601) | F3: محمد محمود ابراهيم (01112057358) | G3: منار احمد سعيد (01092708033) | H3: مصطفى عبد الراضى صديق (01226696153) | I3: ---------- | J3: ---------- | K3: سعيد السيد محمد السيد محمد سابق (01203394950) | L3: احمد عزت الشيخ (01226872660) | M3: ---------- | N3: ---------- | O3: ----------
B4: ---------- | C4: ---------- | D4: ---------- | E4: أحمد رجب محمد (01273127265) | F4: احمد ايهاب محمد عواد (01032298339) | G4: منار عواد عبدالعال عواد (01001915861) | H4: Ziad said mohamed (01028577876) | I4: ---------- | J4: ---------- | K4: أحمد زيدان (01110524147) | L4: ريهام سعد عبدالرحمن (01124867574) | M4: ---------- | N4: ---------- | O4: ----------
B5: ---------- | C5: ---------- | D5: ---------- | E5: عمر حسن محمد حسن حجازي (01019701020) | F5: احمد ناصر (01553479200) | G5: عبدالمسيح مكرم (01203267885) | H5: احمد حسين أحمد (01001877491) | I5: ---------- | J5: ---------- | K5: منة السيد عبد الباقي (01274588193) | L5: رؤى أحمد عبدالحميد البليهي (01021284862) | M5: ---------- | N5: ---------- | O5: ----------
B6: ---------- | C6: ---------- | D6: ---------- | E6: كارين باسم صومائيل (01274209975) | F6: محمد عمرو محمد عبدالباقي (01151653320) | G6: مها حسين السيد (01012349071) | H6: شهاب احمد حلمي (01055979002) | I6: ---------- | J6: ---------- | K6: احمد حسام الدين صلاح (01065567736) | L6: الاء الحداد (01033882560) | M6: ---------- | N6: ---------- | O6: ----------
B7: ---------- | C7: ---------- | D7: ---------- | E7: روان ياسر سليم (01005005160) | F7: مي طارق نهاد (01287477488) | G7: أعناب طارق عوض (01146334179) | H7: منه الله هشام السيد (01002996214) | I7: ---------- | J7: ---------- | K7: بلال أحمد (01066883767) | L7: تقى عماد حسني (01119716276) | M7: ---------- | N7: ---------- | O7: ----------
B8: ---------- | C8: ---------- | D8: ---------- | E8: هديل نادي محند (01033032220) | F8: يوسف عاطف رزق الله (01148183647) | G8: Sara Refaat (01220039613) | H8: احمدنوید قیومی (01104573242) | I8: ---------- | J8: ---------- | K8: ---------- | L8: ---------- | M8: ---------- | N8: ---------- | O8: ----------
B9: ---------- | C9: ---------- | D9: ---------- | E9: مي خالد ابوزيد (01023578224) | F9: Mohamed Ahmed | G9: هديل هشام منصور الوشاحي (01227221344) | H9: شيماء رمضان سعد (01021468731) | I9: ---------- | J9: ---------- | K9: ---------- | L9: ---------- | M9: ---------- | N9: ---------- | O9: ----------
B10: ---------- | C10: ---------- | D10: ---------- | E10: رنيم حاتم رفيق بسيسو (01144758373) | F10: ---------- | G10: ---------- | H10: شدو محمد شلتوت (1550336384) | I10: ---------- | J10: ---------- | K10: ---------- | L10: ---------- | M10: ---------- | N10: ---------- | O10: ----------
A11: 2026-02-02 الاثنين | B11: ---------- | C11: ---------- | D11: ---------- | E11: ---------- | F11: ---------- | G11: ---------- | H11: ---------- | I11: ---------- | J11: ---------- | K11: ---------- | L11: ---------- | M11: ---------- | N11: احمد حسام الدين صلاح (01065567736) | O11: سعيد السيد محمد السيد محمد سابق (01203394950) | P11: =HYPERLINK("#مجمع!B" & 2, "ورديات اليوم مجمعة") -> ورديات اليوم مجمعة
B12: ---------- | C12: ---------- | D12: ---------- | E12: ---------- | F12: ---------- | G12: ---------- | H12: ---------- | I12: ---------- | J12: ---------- | K12: ---------- | L12: ---------- | M12: ---------- | N12: بلال أحمد (01066883767) | O12: دانه طارق (01012809042)
B13: ---------- | C13: ---------- | D13: ---------- | E13: ---------- | F13: ---------- | G13: ---------- | H13: ---------- | I13: ---------- | J13: ---------- | K13: ---------- | L13: ---------- | M13: ---------- | N13: أحمد رجب محمد (01273127265) | O13: مريم السيد أحمد خيرالله (01099882992)
B14: ---------- | C14: ---------- | D14: ---------- | E14: ---------- | F14: ---------- | G14: ---------- | H14: ---------- | I14: ---------- | J14: ---------- | K14: ---------- | L14: ---------- | M14: ---------- | N14: مصطفى عبد الراضى صديق (01226696153) | O14: هديل هشام منصور الوشاحي (01227221344)
B15: ---------- | C15: ---------- | D15: ---------- | E15: ---------- | F15: ---------- | G15: ---------- | H15: ---------- | I15: ---------- | J15: ---------- | K15: ---------- | L15: ---------- | M15: ---------- | N15: منار احمد سعيد (01092708033) | O15: شيماء رمضان سعد (01021468731)
B16: ---------- | C16: ---------- | D16: ---------- | E16: ---------- | F16: ---------- | G16: ---------- | H16: ---------- | I16: ---------- | J16: ---------- | K16: ---------- | L16: ---------- | M16: ---------- | N16: أعناب طارق عوض (01146334179) | O16: ----------
B17: ---------- | C17: ---------- | D17: ---------- | E17: ---------- | F17: ---------- | G17: ---------- | H17: ---------- | I17: ---------- | J17: ---------- | K17: ---------- | L17: ---------- | M17: ---------- | N17: زينة أشرف حسين (01067196820) | O17: ----------
B18: ---------- | C18: ---------- | D18: ---------- | E18: ---------- | F18: ---------- | G18: ---------- | H18: ---------- | I18: ---------- | J18: ---------- | K18: ---------- | L18: ---------- | M18: ---------- | N18: زينة أشرف حسين (01067196820) | O18: ----------
A19: 2026-02-03 الثلاثاء | B19: ---------- | C19: ---------- | D19: ---------- | E19: ---------- | F19: ---------- | G19: ---------- | H19: ---------- | I19: ---------- | J19: ---------- | K19: ---------- | L19: ---------- | M19: محمد الجمل (01091463337) | N19: محمود عبد المحسن إبراهيم (01062086612) | O19: احمد عزت الشيخ (01226872660) | P19: =HYPERLINK("#مجمع!B" & 3, "ورديات اليوم مجمعة") -> ورديات اليوم مجمعة
B20: ---------- | C20: ---------- | D20: ---------- | E20: ---------- | F20: ---------- | G20: ---------- | H20: ---------- | I20: ---------- | J20: ---------- | K20: ---------- | L20: ---------- | M20: احمد عزت الشيخ (01226872660) | N20: Youssef elsemary (01126286820) | O20: محمد محمود ابراهيم (01112057358)
B21: ---------- | C21: ---------- | D21: ---------- | E21: ---------- | F21: ---------- | G21: ---------- | H21: ---------- | I21: ---------- | J21: ---------- | K21: ---------- | L21: ---------- | M21: مي خالد ابوزيد (01023578224) | N21: Sara Refaat (01220039613) | O21: مي طارق نهاد (01287477488)
B22: ---------- | C22: ---------- | D22: ---------- | E22: ---------- | F22: ---------- | G22: ---------- | H22: ---------- | I22: ---------- | J22: ---------- | K22: ---------- | L22: ---------- | M22: ---------- | N22: أعناب طارق عوض (01146334179) | O22: محمد الجمل (01091463337)
B23: ---------- | C23: ---------- | D23: ---------- | E23: ---------- | F23: ---------- | G23: ---------- | H23: ---------- | I23: ---------- | J23: ---------- | K23: ---------- | L23: ---------- | M23: ---------- | N23: استيفن مدحت منير (01200226122) | O23: ----------
B24: ---------- | C24: ---------- | D24: ---------- | E24: ---------- | F24: ---------- | G24: ---------- | H24: ---------- | I24: ---------- | J24: ---------- | K24: ---------- | L24: ---------- | M24: ---------- | N24: Mohamed Ahmed | O24: ----------
A25: 2026-02-04 الأربعاء | B25: ---------- | C25: ---------- | D25: ---------- | E25: ---------- | F25: ---------- | G25: ---------- | H25: ---------- | I25: ---------- | J25: ---------- | K25: ---------- | L25: ---------- | M25: ---------- | N25: سلمى أبوالعلا (01124166114) | O25: محمد عمرو محمد عبدالباقي (01151653320) | P25: =HYPERLINK("#مجمع!B" & 4, "ورديات اليوم مجمعة") -> ورديات اليوم مجمعة
B26: ---------- | C26: ---------- | D26: ---------- | E26: ---------- | F26: ---------- | G26: ---------- | H26: ---------- | I26: ---------- | J26: ---------- | K26: ---------- | L26: ---------- | M26: ---------- | N26: رنيم حاتم رفيق بسيسو (01144758373) | O26: الاء الحداد (01033882560)
B27: ---------- | C27: ---------- | D27: ---------- | E27: ---------- | F27: ---------- | G27: ---------- | H27: ---------- | I27: ---------- | J27: ---------- | K27: ---------- | L27: ---------- | M27: ---------- | N27: روان ياسر سليم (01005005160) | O27: احمد حسين أحمد (01001877491)
B28: ---------- | C28: ---------- | D28: ---------- | E28: ---------- | F28: ---------- | G28: ---------- | H28: ---------- | I28: ---------- | J28: ---------- | K28: ---------- | L28: ---------- | M28: ---------- | N28: عبدالمسيح مكرم (01203267885) | O28: Mohamed Ahmed
B29: ---------- | C29: ---------- | D29: ---------- | E29: ---------- | F29: ---------- | G29: ---------- | H29: ---------- | I29: ---------- | J29: ---------- | K29: ---------- | L29: ---------- | M29: ---------- | N29: مينا رومانى عبده (01212866642) | O29: ----------
B30: ---------- | C30: ---------- | D30: ---------- | E30: ---------- | F30: ---------- | G30: ---------- | H30: ---------- | I30: ---------- | J30: ---------- | K30: ---------- | L30: ---------- | M30: ---------- | N30: هديل نادي محند (01033032220) | O30: ----------
A31: 2026-02-05 الخميس | B31: ---------- | C31: ---------- | D31: ---------- | E31: ---------- | F31: ---------- | G31: ---------- | H31: ---------- | I31: ---------- | J31: ---------- | K31: ---------- | L31: ---------- | M31: ---------- | N31: Ziad said mohamed (01028577876) | O31: احمد عزت الشيخ (01226872660) | P31: =HYPERLINK("#مجمع!B" & 5, "ورديات اليوم مجمعة") -> ورديات اليوم مجمعة
B32: ---------- | C32: ---------- | D32: ---------- | E32: ---------- | F32: ---------- | G32: ---------- | H32: ---------- | I32: ---------- | J32: ---------- | K32: ---------- | L32: ---------- | M32: ---------- | N32: منه الله هشام السيد (01002996214) | O32: شهاب احمد حلمي (01055979002)
B33: ---------- | C33: ---------- | D33: ---------- | E33: ---------- | F33: ---------- | G33: ---------- | H33: ---------- | I33: ---------- | J33: ---------- | K33: ---------- | L33: ---------- | M33: ---------- | N33: عمر حسن محمد حسن حجازي (01019701020) | O33: Mohamed Ahmed
B34: ---------- | C34: ---------- | D34: ---------- | E34: ---------- | F34: ---------- | G34: ---------- | H34: ---------- | I34: ---------- | J34: ---------- | K34: ---------- | L34: ---------- | M34: ---------- | N34: بلال جودة (01066199644) | O34: ----------
B35: ---------- | C35: ---------- | D35: ---------- | E35: ---------- | F35: ---------- | G35: ---------- | H35: ---------- | I35: ---------- | J35: ---------- | K35: ---------- | L35: ---------- | M35: ---------- | N35: سندس أحمد سيد (01156131096) | O35: ----------
A36: 2026-02-06 الجمعة | B36: عمر محمد سيد (01000688544) | C36: شيماء رمضان سعد (01021468731) | D36: ---------- | E36: رنا اكرم احمد (01122182132) | F36: أحمد زيدان (01110524147) | G36: مصطفى محمد علي محمد بدر (01150245681) | H36: احمد حسين أحمد (01001877491) | I36: عبدالمسيح مكرم (01203267885) | J36: شيماء رمضان سعد (01021468731) | K36: ملك محمد فؤاد (01001721072) | L36: محمد الجمل (01091463337) | M36: ---------- | N36: ---------- | O36: ---------- | P36: =HYPERLINK("#مجمع!B" & 6, "ورديات اليوم مجمعة") -> ورديات اليوم مجمعة
B37: ---------- | C37: ---------- | D37: ---------- | E37: رنيم حاتم رفيق بسيسو (01144758373) | F37: شدو محمد شلتوت (1550336384) | G37: حنان النبوى محمد (01067888751) | H37: بلال جودة (01066199644) | I37: ---------- | J37: ---------- | K37: بلال جودة (01066199644) | L37: احمد عزت الشيخ (01226872660) | M37: ---------- | N37: ---------- | O37: ----------
B38: ---------- | C38: ---------- | D38: ---------- | E38: مها حسين السيد (01012349071) | F38: مي طارق نهاد (01287477488) | G38: عمرو عبدالغفار حمزة (01014246636) | H38: عمر حسن محمد حسن حجازي (01019701020) | I38: ---------- | J38: ---------- | K38: Marwan Ayman (01149894940) | L38: يوسف طه السيد (01207620695) | M38: ---------- | N38: ---------- | O38: ----------
B39: ---------- | C39: ---------- | D39: ---------- | E39: محمد خالد محمد (01008204601) | F39: عمرو وائل سرور (01023140340) | G39: Youssef elsemary (01126286820) | H39: نورهان محمد (0112 826 8287) | I39: ---------- | J39: ---------- | K39: أحمد زيدان (01110524147) | L39: سندس أحمد سيد (01156131096) | M39: ---------- | N39: ---------- | O39: ----------
B40: ---------- | C40: ---------- | D40: ---------- | E40: كارين باسم صومائيل (01274209975) | F40: الاء الحداد (01033882560) | G40: مريم السيد أحمد خيرالله (01099882992) | H40: احمدنوید قیومی (01104573242) | I40: ---------- | J40: ---------- | K40: ريهام سعد عبدالرحمن (01124867574) | L40: Mohamed Ahmed | M40: ---------- | N40: ---------- | O40: ----------
...

Sheet مجمع
A1: اليوم | B1: الورديات مجمعة
A2: 2026-02-01 الأحد | B2: ="" & "■■ " & 'الجدول'!B1 & " ■■" & CHAR(10) & "• " & 'الجدول'!B2 & CHAR(10) & "• " & 'الجدول'!B3 & CHAR(10) & "• " & 'الجدول'!B4 & CHAR(10) & "• " & 'الجدول'!B5 & CHAR(10) & "• " & 'الجدول'!B6 & CHAR(10) & "• " & 'الجدول'!B7 & CHAR(10) & "• " & 'الجدول'!B8 & CHAR(10) & "• " & 'الجدول'!B9 & CHAR(10) & "• " & 'الجدول'!B10 & CHAR(10) & CHAR(10) & "■■ " & 'الجدول'!C1 & " ■■" & CHAR(10) & "• " & 'الجدول'!C2 & CHAR(10) & "• " & 'الجدول'!C3 & CHAR(10) & "• " & 'الجدول'!C4 & CHAR(10) & "• " & 'الجدول'!C5 & CHAR(10) & "• " & 'الجدول'!C6 & CHAR(10) & "• " & 'الجدول'!C7 & CHAR(10) & "• " & 'الجدول'!C8 & CHAR(10) & "• " & 'الجدول'!C9 & CHAR(10) & "• " & 'الجدول'!C10 & CHAR(10) & CHAR(10) & "■■ " & 'الجدول'!D1 & " ■■" & CHAR(10) & "• " & 'الجدول'!D2 & CHAR(10) & "• " & 'الجدول'!D3 & CHAR(10) & "• " & 'الجدول'!D4 & CHAR(10) & "• " & 'الجدول'!D5 & CHAR(10) & "• " & 'الجدول'!D6 & CHAR(10) & "• " & 'الجدول'!D7 & CHAR(10) & "• " & 'الجدول'!D8 & CHAR(10) & "• " & 'الجدول'!D9 & CHAR(10) & "• " & 'الجدول'!D10 & CHAR(10) & CHAR(10) & "■■ " & 'الجدول'!E1 & " ■■" & CHAR(10) & "• " & 'الجدول'!E2 & CHAR(10) & "• " & 'الجدول'!E3 & CHAR(10) & "• " & 'الجدول'!E4 & CHAR(10) & "• " & 'الجدول'!E5 & CHAR(10) & "• " & 'الجدول'!E6 & CHAR(10) & "• " & 'الجدول'!E7 & CHAR(10) & "• " & 'الجدول'!E8 & CHAR(10) & "• " & 'الجدول'!E9 & CHAR(10) & "• " & 'الجدول'!E10 & CHAR(10) & CHAR(10) & "■■ " & 'الجدول'!F1 & " ■■" & CHAR(10) & "• " & 'الجدول'!F2 & CHAR(10) & "• " & 'الجدول'!F3 & CHAR(10) & "• " & 'الجدول'!F4 & CHAR(10) & "• " & 'الجدول'!F5 & CHAR(10) & "• " & 'الجدول'!F6 & CHAR(10) & "• " & 'الجدول'!F7 & CHAR(10) & "• " & 'الجدول'!F8 & CHAR(10) & "• " & 'الجدول'!F9 & CHAR(10) & "• " & 'الجدول'!F10 & CHAR(10) & CHAR(10) & "■■ " & 'الجدول'!G1 & " ■■" & CHAR(10) & "• " & 'الجدول'!G2 & CHAR(10) & "• " & 'الجدول'!G3 & CHAR(10) & "• " & 'الجدول'!G4 & CHAR(10) & "• " & 'الجدول'!G5 & CHAR(10) & "• " & 'الجدول'!G6 & CHAR(10) & "• " & 'الجدول'!G7 & CHAR(10) & "• " & 'الجدول'!G8 & CHAR(10) & "• " & 'الجدول'!G9 & CHAR(10) & "• " & 'الجدول'!G10 & CHAR(10) & CHAR(10) & "■■ " & 'الجدول'!H1 & " ■■" & CHAR(10) & "• " & 'الجدول'!H2 & CHAR(10) & "• " & 'الجدول'!H3 & CHAR(10) & "• " & 'الجدول'!H4 & CHAR(10) & "• " & 'الجدول'!H5 & CHAR(10) & "• " & 'الجدول'!H6 & CHAR(10) & "• " & 'الجدول'!H7 & CHAR(10) & "• " & 'الجدول'!H8 & CHAR(10) & "• " & 'الجدول'!H9 & CHAR(10) & "• " & 'الجدول'!H10 & CHAR(10) & CHAR(10) & "■■ " & 'الجدول'!I1 & " ■■" & CHAR(10) & "• " & 'الجدول'!I2 & CHAR(10) & "• " & 'الجدول'!I3 & CHAR(10) & "• " & 'الجدول'!I4 & CHAR(10) & "• " & 'الجدول'!I5 & CHAR(10) & "• " & 'الجدول'!I6 & CHAR(10) & "• " & 'الجدول'!I7 & CHAR(10) & "• " & 'الجدول'!I8 & CHAR(10) & "• " & 'الجدول'!I9 & CHAR(10) & "• " & 'الجدول'!I10 & CHAR(10) & CHAR(10) & "■■ " & 'الجدول'!J1 & " ■■" & CHAR(10) & "• " & 'الجدول'!J2 & CHAR(10) & "• " & 'الجدول'!J3 & CHAR(10) & "• " & 'الجدول'!J4 & CHAR(10) & "• " & 'الجدول'!J5 & CHAR(10) & "• " & 'الجدول'!J6 & CHAR(10) & "• " & 'الجدول'!J7 & CHAR(10) & "• " & 'الجدول'!J8 & CHAR(10) & "• " & 'الجدول'!J9 & CHAR(10) & "• " & 'الجدول'!J10 & CHAR(10) & CHAR(10) & "■■ " & 'الجدول'!K1 & " ■■" & CHAR(10) & "• " & 'الجدول'!K2 & CHAR(10) & "• " & 'الجدول'!K3 & CHAR(10) & "• " & 'الجدول'!K4 & CHAR(10) & "• " & 'الجدول'!K5 & CHAR(10) & "• " & 'الجدول'!K6 & CHAR(10) & "• " & 'الجدول'!K7 & CHAR(10) & "• " & 'الجدول'!K8 & CHAR(10) & "• " & 'الجدول'!K9 & CHAR(10) & "• " & 'الجدول'!K10 & CHAR(10) & CHAR(10) & "■■ " & 'الجدول'!L1 & " ■■" & CHAR(10) & "• " & 'الجدول'!L2 & CHAR(10) & "• " & 'الجدول'!L3 & CHAR(10) & "• " & 'الجدول'!L4 & CHAR(10) & "• " & 'الجدول'!L5 & CHAR(10) & "• " & 'الجدول'!L6 & CHAR(10) & "• " & 'الجدول'!L7 & CHAR(10) & "• " & 'الجدول'!L8 & CHAR(10) & "• " & 'الجدول'!L9 & CHAR(10) & "• " & 'الجدول'!L10 & CHAR(10) & CHAR(10) & "■■ " & 'الجدول'!M1 & " ■■" & CHAR(10) & "• " & 'الجدول'!M2 & CHAR(10) & "• " & 'الجدول'!M3 & CHAR(10) & "• " & 'الجدول'!M4 & CHAR(10) & "• " & 'الجدول'!M5 & CHAR(10) & "• " & 'الجدول'!M6 & CHAR(10) & "• " & 'الجدول'!M7 & CHAR(10) & "• " & 'الجدول'!M8 & CHAR(10) & "• " & 'الجدول'!M9 & CHAR(10) & "• " & 'الجدول'!M10 & CHAR(10) & CHAR(10) & "■■ " & 'الجدول'!N1 & " ■■" & CHAR(10) & "• " & 'الجدول'!N2 & CHAR(10) & "• " & 'الجدول'!N3 & CHAR(10) & "• " & 'الجدول'!N4 & CHAR(10) & "• " & 'الجدول'!N5 & CHAR(10) & "• " & 'الجدول'!N6 & CHAR(10) & "• " & 'الجدول'!N7 & CHAR(10) & "• " & 'الجدول'!N8 & CHAR(10) & "• " & 'الجدول'!N9 & CHAR(10) & "• " & 'الجدول'!N10 & CHAR(10) & CHAR(10) & "■■ " & 'الجدول'!O1 & " ■■" & CHAR(10) & "• " & 'الجدول'!O2 & CHAR(10) & "• " & 'الجدول'!O3 & CHAR(10) & "• " & 'الجدول'!O4 & CHAR(10) & "• " & 'الجدول'!O5 & CHAR(10) & "• " & 'الجدول'!O6 & CHAR(10) & "• " & 'الجدول'!O7 & CHAR(10) & "• " & 'الجدول'!O8 & CHAR(10) & "• " & 'الجدول'!O9 & CHAR(10) & "• " & 'الجدول'!O10 & CHAR(10) & CHAR(10) -> ■■ ER ADMISSION-NIGHT-🚨🌙 ■■ • بلال جودة (01066199644) • ---------- • ---------- • ---------- • ---------- • ---------- • ---------- • ---------- • ---------- ■■ ER ADMISSIONS -DAY-🚨☀️ ■■ • سلمى أبوالعلا (01124166114) • ---------- • ---------- • ---------- • ---------- • ---------- • ---------- • ---------- • ---------- ■■ ER-clinic Day ☀️🚨 ■■ • دانه طارق (01012809042) • ---------- • ---------- • ---------- • ---------- • ---------- • ---------- • ---------- • ---------- ■■ ER GENERAL-DAY-🚨☀️ ■■ • استيفن مدحت منير (01200226122) • محمد خالد محمد (01008204601) • أحمد رجب محمد (01273127265) • عمر حسن محمد حسن حجازي (01019701020) • كارين باسم صومائيل (01274209975) • روان ياسر سليم (01005005160) • هديل نادي محند (01033032220) • مي خالد ابوزيد (01023578224) • رنيم حاتم رفيق بسيسو (01144758373) ■■ ER GENERAL-NIGHT-🚨🌙 ■■ • عمرو وائل سرور (01023140340) • محمد محمود ابراهيم (01112057358) • احمد ايهاب محمد عواد (01032298339) • احمد ناصر (01553479200) • محمد عمرو محمد عبدالباقي (01151653320) • مي طارق نهاد (01287477488) • يوسف عاطف رزق الله (01148183647) • Mohamed Ahmed • ---------- ■■ ER PT-DAY-🚨☀️ ■■ • مينا رومانى عبده (01212866642) • منار احمد سعيد (01092708033) • منار عواد عبدالعال عواد (01001915861) • عبدالمسيح مكرم (01203267885) • مها حسين السيد (01012349071) • أعناب طارق عوض (01146334179) • Sara Refaat (01220039613) • هديل هشام منصور الوشاحي (01227221344) • ---------- ■■ ER PT-NIGHT-🚨🌙 ■■ • سندس أحمد سيد (01156131096) • مصطفى عبد الراضى صديق (01226696153) • Ziad said mohamed (01028577876) • احمد حسين أحمد (01001877491) • شهاب احمد حلمي (01055979002) • منه الله هشام السيد (01002996214) • احمدنوید قیومی (01104573242) • شيماء رمضان سعد (01021468731) • شدو محمد شلتوت (1550336384) ■■ ER TRIAGE-DAY-🚨☀️ ■■ • كارين روماني راشد (01102663062) • ---------- • ---------- • ---------- • ---------- • ---------- • ---------- • ---------- • ---------- ■■ ER TRIAGE-NIGHT-🚨🌙 ■■ • ملك محمد فؤاد (01001721072) • ---------- • ---------- • ---------- • ---------- • ---------- • ---------- • ---------- • ---------- ■■ ER WARD-DAY-🚨☀️ ■■ • محمود عبد المحسن إبراهيم (01062086612) • سعيد السيد محمد السيد محمد سابق (01203394950) • أحمد زيدان (01110524147) • منة السيد عبد الباقي (01274588193) • احمد حسام الدين صلاح (01065567736) • بلال أحمد (01066883767) • ---------- • ---------- • ---------- ■■ ER WARD-NIGHT-🚨🌙 ■■ • محمد الجمل (01091463337) • احمد عزت الشيخ (01226872660) • ريهام سعد عبدالرحمن (01124867574) • رؤى أحمد عبدالحميد البليهي (01021284862) • الاء الحداد (01033882560) • تقى عماد حسني (01119716276) • ---------- • ---------- • ---------- ■■ 🗡️LISTA ■■ • ---------- • ---------- • ---------- • ---------- • ---------- • ---------- • ---------- • ---------- • ---------- ■■ WARD-DAY-☀️ ■■ • ---------- • ---------- • ---------- • ---------- • ---------- • ---------- • ---------- • ---------- • ---------- ■■ WARD-NIGHT-🌙 ■■ • ---------- • ---------- • ---------- • ---------- • ---------- • ---------- • ---------- • ---------- • ---------- | C2: =HYPERLINK("#الجدول!A" & 1, "الجدول الأساسي") -> الجدول الأساسي
A3: 2026-02-02 الاثنين | B3: ="" & "■■ " & 'الجدول'!B1 & " ■■" & CHAR(10) & "• " & 'الجدول'!B11 & CHAR(10) & "• " & 'الجدول'!B12 & CHAR(10) & "• " & 'الجدول'!B13 & CHAR(10) & "• " & 'الجدول'!B14 & CHAR(10) & "• " & 'الجدول'!B15 & CHAR(10) & "• " & 'الجدول'!B16 & CHAR(10) & "• " & 'الجدول'!B17 & CHAR(10) & "• " & 'الجدول'!B18 & CHAR(10) & CHAR(10) & "■■ " & 'الجدول'!C1 & " ■■" & CHAR(10) & "• " & 'الجدول'!C11 & CHAR(10) & "• " & 'الجدول'!C12 & CHAR(10) & "• " & 'الجدول'!C13 & CHAR(10) & "• " & 'الجدول'!C14 & CHAR(10) & "• " & 'الجدول'!C15 & CHAR(10) & "• " & 'الجدول'!C16 & CHAR(10) & "• " & 'الجدول'!C17 & CHAR(10) & "• " & 'الجدول'!C18 & CHAR(10) & CHAR(10) & "■■ " & 'الجدول'!D1 & " ■■" & CHAR(10) & "• " & 'الجدول'!D11 & CHAR(10) & "• " & 'الجدول'!D12 & CHAR(10) & "• " & 'الجدول'!D13 & CHAR(10) & "• " & 'الجدول'!D14 & CHAR(10) & "• " & 'الجدول'!D15 & CHAR(10) & "• " & 'الجدول'!D16 & CHAR(10) & "• " & 'الجدول'!D17 & CHAR(10) & "• " & 'الجدول'!D18 & CHAR(10) & CHAR(10) & "■■ " & 'الجدول'!E1 & " ■■" & CHAR(10) & "• " & 'الجدول'!E11 & CHAR(10) & "• " & 'الجدول'!E12 & CHAR(10) & "• " & 'الجدول'!E13 & CHAR(10) & "• " & 'الجدول'!E14 & CHAR(10) & "• " & 'الجدول'!E15 & CHAR(10) & "• " & 'الجدول'!E16 & CHAR(10) & "• " & 'الجدول'!E17 & CHAR(10) & "• " & 'الجدول'!E18 & CHAR(10) & CHAR(10) & "■■ " & 'الجدول'!F1 & " ■■" & CHAR(10) & "• " & 'الجدول'!F11 & CHAR(10) & "• " & 'الجدول'!F12 & CHAR(10) & "• " & 'الجدول'!F13 & CHAR(10) & "• " & 'الجدول'!F14 & CHAR(10) & "• " & 'الجدول'!F15 & CHAR(10) & "• " & 'الجدول'!F16 & CHAR(10) & "• " & 'الجدول'!F17 & CHAR(10) & "• " & 'الجدول'!F18 & CHAR(10) & CHAR(10) & "■■ " & 'الجدول'!G1 & " ■■" & CHAR(10) & "• " & 'الجدول'!G11 & CHAR(10) & "• " & 'الجدول'!G12 & CHAR(10) & "• " & 'الجدول'!G13 & CHAR(10) & "• " & 'الجدول'!G14 & CHAR(10) & "• " & 'الجدول'!G15 & CHAR(10) & "• " & 'الجدول'!G16 & CHAR(10) & "• " & 'الجدول'!G17 & CHAR(10) & "• " & 'الجدول'!G18 & CHAR(10) & CHAR(10) & "■■ " & 'الجدول'!H1 & " ■■" & CHAR(10) & "• " & 'الجدول'!H11 & CHAR(10) & "• " & 'الجدول'!H12 & CHAR(10) & "• " & 'الجدول'!H13 & CHAR(10) & "• " & 'الجدول'!H14 & CHAR(10) & "• " & 'الجدول'!H15 & CHAR(10) & "• " & 'الجدول'!H16 & CHAR(10) & "• " & 'الجدول'!H17 & CHAR(10) & "• " & 'الجدول'!H18 & CHAR(10) & CHAR(10) & "■■ " & 'الجدول'!I1 & " ■■" & CHAR(10) & "• " & 'الجدول'!I11 & CHAR(10) & "• " & 'الجدول'!I12 & CHAR(10) & "• " & 'الجدول'!I13 & CHAR(10) & "• " & 'الجدول'!I14 & CHAR(10) & "• " & 'الجدول'!I15 & CHAR(10) & "• " & 'الجدول'!I16 & CHAR(10) & "• " & 'الجدول'!I17 & CHAR(10) & "• " & 'الجدول'!I18 & CHAR(10) & CHAR(10) & "■■ " & 'الجدول'!J1 & " ■■" & CHAR(10) & "• " & 'الجدول'!J11 & CHAR(10) & "• " & 'الجدول'!J12 & CHAR(10) & "• " & 'الجدول'!J13 & CHAR(10) & "• " & 'الجدول'!J14 & CHAR(10) & "• " & 'الجدول'!J15 & CHAR(10) & "• " & 'الجدول'!J16 & CHAR(10) & "• " & 'الجدول'!J17 & CHAR(10) & "• " & 'الجدول'!J18 & CHAR(10) & CHAR(10) & "■■ " & 'الجدول'!K1 & " ■■" & CHAR(10) & "• " & 'الجدول'!K11 & CHAR(10) & "• " & 'الجدول'!K12 & CHAR(10) & "• " & 'الجدول'!K13 & CHAR(10) & "• " & 'الجدول'!K14 & CHAR(10) & "• " & 'الجدول'!K15 & CHAR(10) & "• " & 'الجدول'!K16 & CHAR(10) & "• " & 'الجدول'!K17 & CHAR(10) & "• " & 'الجدول'!K18 & CHAR(10) & CHAR(10) & "■■ " & 'الجدول'!L1 & " ■■" & CHAR(10) & "• " & 'الجدول'!L11 & CHAR(10) & "• " & 'الجدول'!L12 & CHAR(10) & "• " & 'الجدول'!L13 & CHAR(10) & "• " & 'الجدول'!L14 & CHAR(10) & "• " & 'الجدول'!L15 & CHAR(10) & "• " & 'الجدول'!L16 & CHAR(10) & "• " & 'الجدول'!L17 & CHAR(10) & "• " & 'الجدول'!L18 & CHAR(10) & CHAR(10) & "■■ " & 'الجدول'!M1 & " ■■" & CHAR(10) & "• " & 'الجدول'!M11 & CHAR(10) & "• " & 'الجدول'!M12 & CHAR(10) & "• " & 'الجدول'!M13 & CHAR(10) & "• " & 'الجدول'!M14 & CHAR(10) & "• " & 'الجدول'!M15 & CHAR(10) & "• " & 'الجدول'!M16 & CHAR(10) & "• " & 'الجدول'!M17 & CHAR(10) & "• " & 'الجدول'!M18 & CHAR(10) & CHAR(10) & "■■ " & 'الجدول'!N1 & " ■■" & CHAR(10) & "• " & 'الجدول'!N11 & CHAR(10) & "• " & 'الجدول'!N12 & CHAR(10) & "• " & 'الجدول'!N13 & CHAR(10) & "• " & 'الجدول'!N14 & CHAR(10) & "• " & 'الجدول'!N15 & CHAR(10) & "• " & 'الجدول'!N16 & CHAR(10) & "• " & 'الجدول'!N17 & CHAR(10) & "• " & 'الجدول'!N18 & CHAR(10) & CHAR(10) & "■■ " & 'الجدول'!O1 & " ■■" & CHAR(10) & "• " & 'الجدول'!O11 & CHAR(10) & "• " & 'الجدول'!O12 & CHAR(10) & "• " & 'الجدول'!O13 & CHAR(10) & "• " & 'الجدول'!O14 & CHAR(10) & "• " & 'الجدول'!O15 & CHAR(10) & "• " & 'الجدول'!O16 & CHAR(10) & "• " & 'الجدول'!O17 & CHAR(10) & "• " & 'الجدول'!O18 & CHAR(10) & CHAR(10) -> ■■ ER ADMISSION-NIGHT-🚨🌙 ■■ • ---------- • ---------- • ---------- • ---------- • ---------- • ---------- • ---------- • ---------- ■■ ER ADMISSIONS -DAY-🚨☀️ ■■ • ---------- • ---------- • ---------- • ---------- • ---------- • ---------- • ---------- • ---------- ■■ ER-clinic Day ☀️🚨 ■■ • ---------- • ---------- • ---------- • ---------- • ---------- • ---------- • ---------- • ---------- ■■ ER GENERAL-DAY-🚨☀️ ■■ • ---------- • ---------- • ---------- • ---------- • ---------- • ---------- • ---------- • ---------- ■■ ER GENERAL-NIGHT-🚨🌙 ■■ • ---------- • ---------- • ---------- • ---------- • ---------- • ---------- • ---------- • ---------- ■■ ER PT-DAY-🚨☀️ ■■ • ---------- • ---------- • ---------- • ---------- • ---------- • ---------- • ---------- • ---------- ■■ ER PT-NIGHT-🚨🌙 ■■ • ---------- • ---------- • ---------- • ---------- • ---------- • ---------- • ---------- • ---------- ■■ ER TRIAGE-DAY-🚨☀️ ■■ • ---------- • ---------- • ---------- • ---------- • ---------- • ---------- • ---------- • ---------- ■■ ER TRIAGE-NIGHT-🚨🌙 ■■ • ---------- • ---------- • ---------- • ---------- • ---------- • ---------- • ---------- • ---------- ■■ ER WARD-DAY-🚨☀️ ■■ • ---------- • ---------- • ---------- • ---------- • ---------- • ---------- • ---------- • ---------- ■■ ER WARD-NIGHT-🚨🌙 ■■ • ---------- • ---------- • ---------- • ---------- • ---------- • ---------- • ---------- • ---------- ■■ 🗡️LISTA ■■ • ---------- • ---------- • ---------- • ---------- • ---------- • ---------- • ---------- • ---------- ■■ WARD-DAY-☀️ ■■ • احمد حسام الدين صلاح (01065567736) • بلال أحمد (01066883767) • أحمد رجب محمد (01273127265) • مصطفى عبد الراضى صديق (01226696153) • منار احمد سعيد (01092708033) • أعناب طارق عوض (01146334179) • زينة أشرف حسين (01067196820) • زينة أشرف حسين (01067196820) ■■ WARD-NIGHT-🌙 ■■ • سعيد السيد محمد السيد محمد سابق (01203394950) • دانه طارق (01012809042) • مريم السيد أحمد خيرالله (01099882992) • هديل هشام منصور الوشاحي (01227221344) • شيماء رمضان سعد (01021468731) • ---------- • ---------- • ---------- | C3: =HYPERLINK("#الجدول!A" & 10, "الجدول الأساسي") -> الجدول الأساسي
A4: 2026-02-03 الثلاثاء | B4: ="" & "■■ " & 'الجدول'!B1 & " ■■" & CHAR(10) & "• " & 'الجدول'!B19 & CHAR(10) & "• " & 'الجدول'!B20 & CHAR(10) & "• " & 'الجدول'!B21 & CHAR(10) & "• " & 'الجدول'!B22 & CHAR(10) & "• " & 'الجدول'!B23 & CHAR(10) & "• " & 'الجدول'!B24 & CHAR(10) & CHAR(10) & "■■ " & 'الجدول'!C1 & " ■■" & CHAR(10) & "• " & 'الجدول'!C19 & CHAR(10) & "• " & 'الجدول'!C20 & CHAR(10) & "• " & 'الجدول'!C21 & CHAR(10) & "• " & 'الجدول'!C22 & CHAR(10) & "• " & 'الجدول'!C23 & CHAR(10) & "• " & 'الجدول'!C24 & CHAR(10) & CHAR(10) & "■■ " & 'الجدول'!D1 & " ■■" & CHAR(10) & "• " & 'الجدول'!D19 & CHAR(10) & "• " & 'الجدول'!D20 & CHAR(10) & "• " & 'الجدول'!D21 & CHAR(10) & "• " & 'الجدول'!D22 & CHAR(10) & "• " & 'الجدول'!D23 & CHAR(10) & "• " & 'الجدول'!D24 & CHAR(10) & CHAR(10) & "■■ " & 'الجدول'!E1 & " ■■" & CHAR(10) & "• " & 'الجدول'!E19 & CHAR(10) & "• " & 'الجدول'!E20 & CHAR(10) & "• " & 'الجدول'!E21 & CHAR(10) & "• " & 'الجدول'!E22 & CHAR(10) & "• " & 'الجدول'!E23 & CHAR(10) & "• " & 'الجدول'!E24 & CHAR(10) & CHAR(10) & "■■ " & 'الجدول'!F1 & " ■■" & CHAR(10) & "• " & 'الجدول'!F19 & CHAR(10) & "• " & 'الجدول'!F20 & CHAR(10) & "• " & 'الجدول'!F21 & CHAR(10) & "• " & 'الجدول'!F22 & CHAR(10) & "• " & 'الجدول'!F23 & CHAR(10) & "• " & 'الجدول'!F24 & CHAR(10) & CHAR(10) & "■■ " & 'الجدول'!G1 & " ■■" & CHAR(10) & "• " & 'الجدول'!G19 & CHAR(10) & "• " & 'الجدول'!G20 & CHAR(10) & "• " & 'الجدول'!G21 & CHAR(10) & "• " & 'الجدول'!G22 & CHAR(10) & "• " & 'الجدول'!G23 & CHAR(10) & "• " & 'الجدول'!G24 & CHAR(10) & CHAR(10) & "■■ " & 'الجدول'!H1 & " ■■" & CHAR(10) & "• " & 'الجدول'!H19 & CHAR(10) & "• " & 'الجدول'!H20 & CHAR(10) & "• " & 'الجدول'!H21 & CHAR(10) & "• " & 'الجدول'!H22 & CHAR(10) & "• " & 'الجدول'!H23 & CHAR(10) & "• " & 'الجدول'!H24 & CHAR(10) & CHAR(10) & "■■ " & 'الجدول'!I1 & " ■■" & CHAR(10) & "• " & 'الجدول'!I19 & CHAR(10) & "• " & 'الجدول'!I20 & CHAR(10) & "• " & 'الجدول'!I21 & CHAR(10) & "• " & 'الجدول'!I22 & CHAR(10) & "• " & 'الجدول'!I23 & CHAR(10) & "• " & 'الجدول'!I24 & CHAR(10) & CHAR(10) & "■■ " & 'الجدول'!J1 & " ■■" & CHAR(10) & "• " & 'الجدول'!J19 & CHAR(10) & "• " & 'الجدول'!J20 & CHAR(10) & "• " & 'الجدول'!J21 & CHAR(10) & "• " & 'الجدول'!J22 & CHAR(10) & "• " & 'الجدول'!J23 & CHAR(10) & "• " & 'الجدول'!J24 & CHAR(10) & CHAR(10) & "■■ " & 'الجدول'!K1 & " ■■" & CHAR(10) & "• " & 'الجدول'!K19 & CHAR(10) & "• " & 'الجدول'!K20 & CHAR(10) & "• " & 'الجدول'!K21 & CHAR(10) & "• " & 'الجدول'!K22 & CHAR(10) & "• " & 'الجدول'!K23 & CHAR(10) & "• " & 'الجدول'!K24 & CHAR(10) & CHAR(10) & "■■ " & 'الجدول'!L1 & " ■■" & CHAR(10) & "• " & 'الجدول'!L19 & CHAR(10) & "• " & 'الجدول'!L20 & CHAR(10) & "• " & 'الجدول'!L21 & CHAR(10) & "• " & 'الجدول'!L22 & CHAR(10) & "• " & 'الجدول'!L23 & CHAR(10) & "• " & 'الجدول'!L24 & CHAR(10) & CHAR(10) & "■■ " & 'الجدول'!M1 & " ■■" & CHAR(10) & "• " & 'الجدول'!M19 & CHAR(10) & "• " & 'الجدول'!M20 & CHAR(10) & "• " & 'الجدول'!M21 & CHAR(10) & "• " & 'الجدول'!M22 & CHAR(10) & "• " & 'الجدول'!M23 & CHAR(10) & "• " & 'الجدول'!M24 & CHAR(10) & CHAR(10) & "■■ " & 'الجدول'!N1 & " ■■" & CHAR(10) & "• " & 'الجدول'!N19 & CHAR(10) & "• " & 'الجدول'!N20 & CHAR(10) & "• " & 'الجدول'!N21 & CHAR(10) & "• " & 'الجدول'!N22 & CHAR(10) & "• " & 'الجدول'!N23 & CHAR(10) & "• " & 'الجدول'!N24 & CHAR(10) & CHAR(10) & "■■ " & 'الجدول'!O1 & " ■■" & CHAR(10) & "• " & 'الجدول'!O19 & CHAR(10) & "• " & 'الجدول'!O20 & CHAR(10) & "• " & 'الجدول'!O21 & CHAR(10) & "• " & 'الجدول'!O22 & CHAR(10) & "• " & 'الجدول'!O23 & CHAR(10) & "• " & 'الجدول'!O24 & CHAR(10) & CHAR(10) -> ■■ ER ADMISSION-NIGHT-🚨🌙 ■■ • ---------- • ---------- • ---------- • ---------- • ---------- • ---------- ■■ ER ADMISSIONS -DAY-🚨☀️ ■■ • ---------- • ---------- • ---------- • ---------- • ---------- • ---------- ■■ ER-clinic Day ☀️🚨 ■■ • ---------- • ---------- • ---------- • ---------- • ---------- • ---------- ■■ ER GENERAL-DAY-🚨☀️ ■■ • ---------- • ---------- • ---------- • ---------- • ---------- • ---------- ■■ ER GENERAL-NIGHT-🚨🌙 ■■ • ---------- • ---------- • ---------- • ---------- • ---------- • ---------- ■■ ER PT-DAY-🚨☀️ ■■ • ---------- • ---------- • ---------- • ---------- • ---------- • ---------- ■■ ER PT-NIGHT-🚨🌙 ■■ • ---------- • ---------- • ---------- • ---------- • ---------- • ---------- ■■ ER TRIAGE-DAY-🚨☀️ ■■ • ---------- • ---------- • ---------- • ---------- • ---------- • ---------- ■■ ER TRIAGE-NIGHT-🚨🌙 ■■ • ---------- • ---------- • ---------- • ---------- • ---------- • ---------- ■■ ER WARD-DAY-🚨☀️ ■■ • ---------- • ---------- • ---------- • ---------- • ---------- • ---------- ■■ ER WARD-NIGHT-🚨🌙 ■■ • ---------- • ---------- • ---------- • ---------- • ---------- • ---------- ■■ 🗡️LISTA ■■ • محمد الجمل (01091463337) • احمد عزت الشيخ (01226872660) • مي خالد ابوزيد (01023578224) • ---------- • ---------- • ---------- ■■ WARD-DAY-☀️ ■■ • محمود عبد المحسن إبراهيم (01062086612) • Youssef elsemary (01126286820) • Sara Refaat (01220039613) • أعناب طارق عوض (01146334179) • استيفن مدحت منير (01200226122) • Mohamed Ahmed ■■ WARD-NIGHT-🌙 ■■ • احمد عزت الشيخ (01226872660) • محمد محمود ابراهيم (01112057358) • مي طارق نهاد (01287477488) • محمد الجمل (01091463337) • ---------- • ---------- | C4: =HYPERLINK("#الجدول!A" & 18, "الجدول الأساسي") -> الجدول الأساسي
A5: 2026-02-04 الأربعاء | B5: ="" & "■■ " & 'الجدول'!B1 & " ■■" & CHAR(10) & "• " & 'الجدول'!B25 & CHAR(10) & "• " & 'الجدول'!B26 & CHAR(10) & "• " & 'الجدول'!B27 & CHAR(10) & "• " & 'الجدول'!B28 & CHAR(10) & "• " & 'الجدول'!B29 & CHAR(10) & "• " & 'الجدول'!B30 & CHAR(10) & CHAR(10) & "■■ " & 'الجدول'!C1 & " ■■" & CHAR(10) & "• " & 'الجدول'!C25 & CHAR(10) & "• " & 'الجدول'!C26 & CHAR(10) & "• " & 'الجدول'!C27 & CHAR(10) & "• " & 'الجدول'!C28 & CHAR(10) & "• " & 'الجدول'!C29 & CHAR(10) & "• " & 'الجدول'!C30 & CHAR(10) & CHAR(10) & "■■ " & 'الجدول'!D1 & " ■■" & CHAR(10) & "• " & 'الجدول'!D25 & CHAR(10) & "• " & 'الجدول'!D26 & CHAR(10) & "• " & 'الجدول'!D27 & CHAR(10) & "• " & 'الجدول'!D28 & CHAR(10) & "• " & 'الجدول'!D29 & CHAR(10) & "• " & 'الجدول'!D30 & CHAR(10) & CHAR(10) & "■■ " & 'الجدول'!E1 & " ■■" & CHAR(10) & "• " & 'الجدول'!E25 & CHAR(10) & "• " & 'الجدول'!E26 & CHAR(10) & "• " & 'الجدول'!E27 & CHAR(10) & "• " & 'الجدول'!E28 & CHAR(10) & "• " & 'الجدول'!E29 & CHAR(10) & "• " & 'الجدول'!E30 & CHAR(10) & CHAR(10) & "■■ " & 'الجدول'!F1 & " ■■" & CHAR(10) & "• " & 'الجدول'!F25 & CHAR(10) & "• " & 'الجدول'!F26 & CHAR(10) & "• " & 'الجدول'!F27 & CHAR(10) & "• " & 'الجدول'!F28 & CHAR(10) & "• " & 'الجدول'!F29 & CHAR(10) & "• " & 'الجدول'!F30 & CHAR(10) & CHAR(10) & "■■ " & 'الجدول'!G1 & " ■■" & CHAR(10) & "• " & 'الجدول'!G25 & CHAR(10) & "• " & 'الجدول'!G26 & CHAR(10) & "• " & 'الجدول'!G27 & CHAR(10) & "• " & 'الجدول'!G28 & CHAR(10) & "• " & 'الجدول'!G29 & CHAR(10) & "• " & 'الجدول'!G30 & CHAR(10) & CHAR(10) & "■■ " & 'الجدول'!H1 & " ■■" & CHAR(10) & "• " & 'الجدول'!H25 & CHAR(10) & "• " & 'الجدول'!H26 & CHAR(10) & "• " & 'الجدول'!H27 & CHAR(10) & "• " & 'الجدول'!H28 & CHAR(10) & "• " & 'الجدول'!H29 & CHAR(10) & "• " & 'الجدول'!H30 & CHAR(10) & CHAR(10) & "■■ " & 'الجدول'!I1 & " ■■" & CHAR(10) & "• " & 'الجدول'!I25 & CHAR(10) & "• " & 'الجدول'!I26 & CHAR(10) & "• " & 'الجدول'!I27 & CHAR(10) & "• " & 'الجدول'!I28 & CHAR(10) & "• " & 'الجدول'!I29 & CHAR(10) & "• " & 'الجدول'!I30 & CHAR(10) & CHAR(10) & "■■ " & 'الجدول'!J1 & " ■■" & CHAR(10) & "• " & 'الجدول'!J25 & CHAR(10) & "• " & 'الجدول'!J26 & CHAR(10) & "• " & 'الجدول'!J27 & CHAR(10) & "• " & 'الجدول'!J28 & CHAR(10) & "• " & 'الجدول'!J29 & CHAR(10) & "• " & 'الجدول'!J30 & CHAR(10) & CHAR(10) & "■■ " & 'الجدول'!K1 & " ■■" & CHAR(10) & "• " & 'الجدول'!K25 & CHAR(10) & "• " & 'الجدول'!K26 & CHAR(10) & "• " & 'الجدول'!K27 & CHAR(10) & "• " & 'الجدول'!K28 & CHAR(10) & "• " & 'الجدول'!K29 & CHAR(10) & "• " & 'الجدول'!K30 & CHAR(10) & CHAR(10) & "■■ " & 'الجدول'!L1 & " ■■" & CHAR(10) & "• " & 'الجدول'!L25 & CHAR(10) & "• " & 'الجدول'!L26 & CHAR(10) & "• " & 'الجدول'!L27 & CHAR(10) & "• " & 'الجدول'!L28 & CHAR(10) & "• " & 'الجدول'!L29 & CHAR(10) & "• " & 'الجدول'!L30 & CHAR(10) & CHAR(10) & "■■ " & 'الجدول'!M1 & " ■■" & CHAR(10) & "• " & 'الجدول'!M25 & CHAR(10) & "• " & 'الجدول'!M26 & CHAR(10) & "• " & 'الجدول'!M27 & CHAR(10) & "• " & 'الجدول'!M28 & CHAR(10) & "• " & 'الجدول'!M29 & CHAR(10) & "• " & 'الجدول'!M30 & CHAR(10) & CHAR(10) & "■■ " & 'الجدول'!N1 & " ■■" & CHAR(10) & "• " & 'الجدول'!N25 & CHAR(10) & "• " & 'الجدول'!N26 & CHAR(10) & "• " & 'الجدول'!N27 & CHAR(10) & "• " & 'الجدول'!N28 & CHAR(10) & "• " & 'الجدول'!N29 & CHAR(10) & "• " & 'الجدول'!N30 & CHAR(10) & CHAR(10) & "■■ " & 'الجدول'!O1 & " ■■" & CHAR(10) & "• " & 'الجدول'!O25 & CHAR(10) & "• " & 'الجدول'!O26 & CHAR(10) & "• " & 'الجدول'!O27 & CHAR(10) & "• " & 'الجدول'!O28 & CHAR(10) & "• " & 'الجدول'!O29 & CHAR(10) & "• " & 'الجدول'!O30 & CHAR(10) & CHAR(10) -> ■■ ER ADMISSION-NIGHT-🚨🌙 ■■ • ---------- • ---------- • ---------- • ---------- • ---------- • ---------- ■■ ER ADMISSIONS -DAY-🚨☀️ ■■ • ---------- • ---------- • ---------- • ---------- • ---------- • ---------- ■■ ER-clinic Day ☀️🚨 ■■ • ---------- • ---------- • ---------- • ---------- • ---------- • ---------- ■■ ER GENERAL-DAY-🚨☀️ ■■ • ---------- • ---------- • ---------- • ---------- • ---------- • ---------- ■■ ER GENERAL-NIGHT-🚨🌙 ■■ • ---------- • ---------- • ---------- • ---------- • ---------- • ---------- ■■ ER PT-DAY-🚨☀️ ■■ • ---------- • ---------- • ---------- • ---------- • ---------- • ---------- ■■ ER PT-NIGHT-🚨🌙 ■■ • ---------- • ---------- • ---------- • ---------- • ---------- • ---------- ■■ ER TRIAGE-DAY-🚨☀️ ■■ • ---------- • ---------- • ---------- • ---------- • ---------- • ---------- ■■ ER TRIAGE-NIGHT-🚨🌙 ■■ • ---------- • ---------- • ---------- • ---------- • ---------- • ---------- ■■ ER WARD-DAY-🚨☀️ ■■ • ---------- • ---------- • ---------- • ---------- • ---------- • ---------- ■■ ER WARD-NIGHT-🚨🌙 ■■ • ---------- • ---------- • ---------- • ---------- • ---------- • ---------- ■■ 🗡️LISTA ■■ • ---------- • ---------- • ---------- • ---------- • ---------- • ---------- ■■ WARD-DAY-☀️ ■■ • سلمى أبوالعلا (01124166114) • رنيم حاتم رفيق بسيسو (01144758373) • روان ياسر سليم (01005005160) • عبدالمسيح مكرم (01203267885) • مينا رومانى عبده (01212866642) • هديل نادي محند (01033032220) ■■ WARD-NIGHT-🌙 ■■ • محمد عمرو محمد عبدالباقي (01151653320) • الاء الحداد (01033882560) • احمد حسين أحمد (01001877491) • Mohamed Ahmed • ---------- • ---------- | C5: =HYPERLINK("#الجدول!A" & 24, "الجدول الأساسي") -> الجدول الأساسي
A6: 2026-02-05 الخميس | B6: ="" & "■■ " & 'الجدول'!B1 & " ■■" & CHAR(10) & "• " & 'الجدول'!B31 & CHAR(10) & "• " & 'الجدول'!B32 & CHAR(10) & "• " & 'الجدول'!B33 & CHAR(10) & "• " & 'الجدول'!B34 & CHAR(10) & "• " & 'الجدول'!B35 & CHAR(10) & CHAR(10) & "■■ " & 'الجدول'!C1 & " ■■" & CHAR(10) & "• " & 'الجدول'!C31 & CHAR(10) & "• " & 'الجدول'!C32 & CHAR(10) & "• " & 'الجدول'!C33 & CHAR(10) & "• " & 'الجدول'!C34 & CHAR(10) & "• " & 'الجدول'!C35 & CHAR(10) & CHAR(10) & "■■ " & 'الجدول'!D1 & " ■■" & CHAR(10) & "• " & 'الجدول'!D31 & CHAR(10) & "• " & 'الجدول'!D32 & CHAR(10) & "• " & 'الجدول'!D33 & CHAR(10) & "• " & 'الجدول'!D34 & CHAR(10) & "• " & 'الجدول'!D35 & CHAR(10) & CHAR(10) & "■■ " & 'الجدول'!E1 & " ■■" & CHAR(10) & "• " & 'الجدول'!E31 & CHAR(10) & "• " & 'الجدول'!E32 & CHAR(10) & "• " & 'الجدول'!E33 & CHAR(10) & "• " & 'الجدول'!E34 & CHAR(10) & "• " & 'الجدول'!E35 & CHAR(10) & CHAR(10) & "■■ " & 'الجدول'!F1 & " ■■" & CHAR(10) & "• " & 'الجدول'!F31 & CHAR(10) & "• " & 'الجدول'!F32 & CHAR(10) & "• " & 'الجدول'!F33 & CHAR(10) & "• " & 'الجدول'!F34 & CHAR(10) & "• " & 'الجدول'!F35 & CHAR(10) & CHAR(10) & "■■ " & 'الجدول'!G1 & " ■■" & CHAR(10) & "• " & 'الجدول'!G31 & CHAR(10) & "• " & 'الجدول'!G32 & CHAR(10) & "• " & 'الجدول'!G33 & CHAR(10) & "• " & 'الجدول'!G34 & CHAR(10) & "• " & 'الجدول'!G35 & CHAR(10) & CHAR(10) & "■■ " & 'الجدول'!H1 & " ■■" & CHAR(10) & "• " & 'الجدول'!H31 & CHAR(10) & "• " & 'الجدول'!H32 & CHAR(10) & "• " & 'الجدول'!H33 & CHAR(10) & "• " & 'الجدول'!H34 & CHAR(10) & "• " & 'الجدول'!H35 & CHAR(10) & CHAR(10) & "■■ " & 'الجدول'!I1 & " ■■" & CHAR(10) & "• " & 'الجدول'!I31 & CHAR(10) & "• " & 'الجدول'!I32 & CHAR(10) & "• " & 'الجدول'!I33 & CHAR(10) & "• " & 'الجدول'!I34 & CHAR(10) & "• " & 'الجدول'!I35 & CHAR(10) & CHAR(10) & "■■ " & 'الجدول'!J1 & " ■■" & CHAR(10) & "• " & 'الجدول'!J31 & CHAR(10) & "• " & 'الجدول'!J32 & CHAR(10) & "• " & 'الجدول'!J33 & CHAR(10) & "• " & 'الجدول'!J34 & CHAR(10) & "• " & 'الجدول'!J35 & CHAR(10) & CHAR(10) & "■■ " & 'الجدول'!K1 & " ■■" & CHAR(10) & "• " & 'الجدول'!K31 & CHAR(10) & "• " & 'الجدول'!K32 & CHAR(10) & "• " & 'الجدول'!K33 & CHAR(10) & "• " & 'الجدول'!K34 & CHAR(10) & "• " & 'الجدول'!K35 & CHAR(10) & CHAR(10) & "■■ " & 'الجدول'!L1 & " ■■" & CHAR(10) & "• " & 'الجدول'!L31 & CHAR(10) & "• " & 'الجدول'!L32 & CHAR(10) & "• " & 'الجدول'!L33 & CHAR(10) & "• " & 'الجدول'!L34 & CHAR(10) & "• " & 'الجدول'!L35 & CHAR(10) & CHAR(10) & "■■ " & 'الجدول'!M1 & " ■■" & CHAR(10) & "• " & 'الجدول'!M31 & CHAR(10) & "• " & 'الجدول'!M32 & CHAR(10) & "• " & 'الجدول'!M33 & CHAR(10) & "• " & 'الجدول'!M34 & CHAR(10) & "• " & 'الجدول'!M35 & CHAR(10) & CHAR(10) & "■■ " & 'الجدول'!N1 & " ■■" & CHAR(10) & "• " & 'الجدول'!N31 & CHAR(10) & "• " & 'الجدول'!N32 & CHAR(10) & "• " & 'الجدول'!N33 & CHAR(10) & "• " & 'الجدول'!N34 & CHAR(10) & "• " & 'الجدول'!N35 & CHAR(10) & CHAR(10) & "■■ " & 'الجدول'!O1 & " ■■" & CHAR(10) & "• " & 'الجدول'!O31 & CHAR(10) & "• " & 'الجدول'!O32 & CHAR(10) & "• " & 'الجدول'!O33 & CHAR(10) & "• " & 'الجدول'!O34 & CHAR(10) & "• " & 'الجدول'!O35 & CHAR(10) & CHAR(10) -> ■■ ER ADMISSION-NIGHT-🚨🌙 ■■ • ---------- • ---------- • ---------- • ---------- • ---------- ■■ ER ADMISSIONS -DAY-🚨☀️ ■■ • ---------- • ---------- • ---------- • ---------- • ---------- ■■ ER-clinic Day ☀️🚨 ■■ • ---------- • ---------- • ---------- • ---------- • ---------- ■■ ER GENERAL-DAY-🚨☀️ ■■ • ---------- • ---------- • ---------- • ---------- • ---------- ■■ ER GENERAL-NIGHT-🚨🌙 ■■ • ---------- • ---------- • ---------- • ---------- • ---------- ■■ ER PT-DAY-🚨☀️ ■■ • ---------- • ---------- • ---------- • ---------- • ---------- ■■ ER PT-NIGHT-🚨🌙 ■■ • ---------- • ---------- • ---------- • ---------- • ---------- ■■ ER TRIAGE-DAY-🚨☀️ ■■ • ---------- • ---------- • ---------- • ---------- • ---------- ■■ ER TRIAGE-NIGHT-🚨🌙 ■■ • ---------- • ---------- • ---------- • ---------- • ---------- ■■ ER WARD-DAY-🚨☀️ ■■ • ---------- • ---------- • ---------- • ---------- • ---------- ■■ ER WARD-NIGHT-🚨🌙 ■■ • ---------- • ---------- • ---------- • ---------- • ---------- ■■ 🗡️LISTA ■■ • ---------- • ---------- • ---------- • ---------- • ---------- ■■ WARD-DAY-☀️ ■■ • Ziad said mohamed (01028577876) • منه الله هشام السيد (01002996214) • عمر حسن محمد حسن حجازي (01019701020) • بلال جودة (01066199644) • سندس أحمد سيد (01156131096) ■■ WARD-NIGHT-🌙 ■■ • احمد عزت الشيخ (01226872660) • شهاب احمد حلمي (01055979002) • Mohamed Ahmed • ---------- • ---------- | C6: =HYPERLINK("#الجدول!A" & 30, "الجدول الأساسي") -> الجدول الأساسي
A7: 2026-02-06 الجمعة | B7: ="" & "■■ " & 'الجدول'!B1 & " ■■" & CHAR(10) & "• " & 'الجدول'!B36 & CHAR(10) & "• " & 'الجدول'!B37 & CHAR(10) & "• " & 'الجدول'!B38 & CHAR(10) & "• " & 'الجدول'!B39 & CHAR(10) & "• " & 'الجدول'!B40 & CHAR(10) & "• " & 'الجدول'!B41 & CHAR(10) & "• " & 'الجدول'!B42 & CHAR(10) & "• " & 'الجدول'!B43 & CHAR(10) & "• " & 'الجدول'!B44 & CHAR(10) & CHAR(10) & "■■ " & 'الجدول'!C1 & " ■■" & CHAR(10) & "• " & 'الجدول'!C36 & CHAR(10) & "• " & 'الجدول'!C37 & CHAR(10) & "• " & 'الجدول'!C38 & CHAR(10) & "• " & 'الجدول'!C39 & CHAR(10) & "• " & 'الجدول'!C40 & CHAR(10) & "• " & 'الجدول'!C41 & CHAR(10) & "• " & 'الجدول'!C42 & CHAR(10) & "• " & 'الجدول'!C43 & CHAR(10) & "• " & 'الجدول'!C44 & CHAR(10) & CHAR(10) & "■■ " & 'الجدول'!D1 & " ■■" & CHAR(10) & "• " & 'الجدول'!D36 & CHAR(10) & "• " & 'الجدول'!D37 & CHAR(10) & "• " & 'الجدول'!D38 & CHAR(10) & "• " & 'الجدول'!D39 & CHAR(10) & "• " & 'الجدول'!D40 & CHAR(10) & "• " & 'الجدول'!D41 & CHAR(10) & "• " & 'الجدول'!D42 & CHAR(10) & "• " & 'الجدول'!D43 & CHAR(10) & "• " & 'الجدول'!D44 & CHAR(10) & CHAR(10) & "■■ " & 'الجدول'!E1 & " ■■" & CHAR(10) & "• " & 'الجدول'!E36 & CHAR(10) & "• " & 'الجدول'!E37 & CHAR(10) & "• " & 'الجدول'!E38 & CHAR(10) & "• " & 'الجدول'!E39 & CHAR(10) & "• " & 'الجدول'!E40 & CHAR(10) & "• " & 'الجدول'!E41 & CHAR(10) & "• " & 'الجدول'!E42 & CHAR(10) & "• " & 'الجدول'!E43 & CHAR(10) & "• " & 'الجدول'!E44 & CHAR(10) & CHAR(10) & "■■ " & 'الجدول'!F1 & " ■■" & CHAR(10) & "• " & 'الجدول'!F36 & CHAR(10) & "• " & 'الجدول'!F37 & CHAR(10) & "• " & 'الجدول'!F38 & CHAR(10) & "• " & 'الجدول'!F39 & CHAR(10) & "• " & 'الجدول'!F40 & CHAR(10) & "• " & 'الجدول'!F41 & CHAR(10) & "• " & 'الجدول'!F42 & CHAR(10) & "• " & 'الجدول'!F43 & CHAR(10) & "• " & 'الجدول'!F44 & CHAR(10) & CHAR(10) & "■■ " & 'الجدول'!G1 & " ■■" & CHAR(10) & "• " & 'الجدول'!G36 & CHAR(10) & "• " & 'الجدول'!G37 & CHAR(10) & "• " & 'الجدول'!G38 & CHAR(10) & "• " & 'الجدول'!G39 & CHAR(10) & "• " & 'الجدول'!G40 & CHAR(10) & "• " & 'الجدول'!G41 & CHAR(10) & "• " & 'الجدول'!G42 & CHAR(10) & "• " & 'الجدول'!G43 & CHAR(10) & "• " & 'الجدول'!G44 & CHAR(10) & CHAR(10) & "■■ " & 'الجدول'!H1 & " ■■" & CHAR(10) & "• " & 'الجدول'!H36 & CHAR(10) & "• " & 'الجدول'!H37 & CHAR(10) & "• " & 'الجدول'!H38 & CHAR(10) & "• " & 'الجدول'!H39 & CHAR(10) & "• " & 'الجدول'!H40 & CHAR(10) & "• " & 'الجدول'!H41 & CHAR(10) & "• " & 'الجدول'!H42 & CHAR(10) & "• " & 'الجدول'!H43 & CHAR(10) & "• " & 'الجدول'!H44 & CHAR(10) & CHAR(10) & "■■ " & 'الجدول'!I1 & " ■■" & CHAR(10) & "• " & 'الجدول'!I36 & CHAR(10) & "• " & 'الجدول'!I37 & CHAR(10) & "• " & 'الجدول'!I38 & CHAR(10) & "• " & 'الجدول'!I39 & CHAR(10) & "• " & 'الجدول'!I40 & CHAR(10) & "• " & 'الجدول'!I41 & CHAR(10) & "• " & 'الجدول'!I42 & CHAR(10) & "• " & 'الجدول'!I43 & CHAR(10) & "• " & 'الجدول'!I44 & CHAR(10) & CHAR(10) & "■■ " & 'الجدول'!J1 & " ■■" & CHAR(10) & "• " & 'الجدول'!J36 & CHAR(10) & "• " & 'الجدول'!J37 & CHAR(10) & "• " & 'الجدول'!J38 & CHAR(10) & "• " & 'الجدول'!J39 & CHAR(10) & "• " & 'الجدول'!J40 & CHAR(10) & "• " & 'الجدول'!J41 & CHAR(10) & "• " & 'الجدول'!J42 & CHAR(10) & "• " & 'الجدول'!J43 & CHAR(10) & "• " & 'الجدول'!J44 & CHAR(10) & CHAR(10) & "■■ " & 'الجدول'!K1 & " ■■" & CHAR(10) & "• " & 'الجدول'!K36 & CHAR(10) & "• " & 'الجدول'!K37 & CHAR(10) & "• " & 'الجدول'!K38 & CHAR(10) & "• " & 'الجدول'!K39 & CHAR(10) & "• " & 'الجدول'!K40 & CHAR(10) & "• " & 'الجدول'!K41 & CHAR(10) & "• " & 'الجدول'!K42 & CHAR(10) & "• " & 'الجدول'!K43 & CHAR(10) & "• " & 'الجدول'!K44 & CHAR(10) & CHAR(10) & "■■ " & 'الجدول'!L1 & " ■■" & CHAR(10) & "• " & 'الجدول'!L36 & CHAR(10) & "• " & 'الجدول'!L37 & CHAR(10) & "• " & 'الجدول'!L38 & CHAR(10) & "• " & 'الجدول'!L39 & CHAR(10) & "• " & 'الجدول'!L40 & CHAR(10) & "• " & 'الجدول'!L41 & CHAR(10) & "• " & 'الجدول'!L42 & CHAR(10) & "• " & 'الجدول'!L43 & CHAR(10) & "• " & 'الجدول'!L44 & CHAR(10) & CHAR(10) & "■■ " & 'الجدول'!M1 & " ■■" & CHAR(10) & "• " & 'الجدول'!M36 & CHAR(10) & "• " & 'الجدول'!M37 & CHAR(10) & "• " & 'الجدول'!M38 & CHAR(10) & "• " & 'الجدول'!M39 & CHAR(10) & "• " & 'الجدول'!M40 & CHAR(10) & "• " & 'الجدول'!M41 & CHAR(10) & "• " & 'الجدول'!M42 & CHAR(10) & "• " & 'الجدول'!M43 & CHAR(10) & "• " & 'الجدول'!M44 & CHAR(10) & CHAR(10) & "■■ " & 'الجدول'!N1 & " ■■" & CHAR(10) & "• " & 'الجدول'!N36 & CHAR(10) & "• " & 'الجدول'!N37 & CHAR(10) & "• " & 'الجدول'!N38 & CHAR(10) & "• " & 'الجدول'!N39 & CHAR(10) & "• " & 'الجدول'!N40 & CHAR(10) & "• " & 'الجدول'!N41 & CHAR(10) & "• " & 'الجدول'!N42 & CHAR(10) & "• " & 'الجدول'!N43 & CHAR(10) & "• " & 'الجدول'!N44 & CHAR(10) & CHAR(10) & "■■ " & 'الجدول'!O1 & " ■■" & CHAR(10) & "• " & 'الجدول'!O36 & CHAR(10) & "• " & 'الجدول'!O37 & CHAR(10) & "• " & 'الجدول'!O38 & CHAR(10) & "• " & 'الجدول'!O39 & CHAR(10) & "• " & 'الجدول'!O40 & CHAR(10) & "• " & 'الجدول'!O41 & CHAR(10) & "• " & 'الجدول'!O42 & CHAR(10) & "• " & 'الجدول'!O43 & CHAR(10) & "• " & 'الجدول'!O44 & CHAR(10) & CHAR(10) -> ■■ ER ADMISSION-NIGHT-🚨🌙 ■■ • عمر محمد سيد (01000688544) • ---------- • ---------- • ---------- • ---------- • ---------- • ---------- • ---------- • ---------- ■■ ER ADMISSIONS -DAY-🚨☀️ ■■ • شيماء رمضان سعد (01021468731) • ---------- • ---------- • ---------- • ---------- • ---------- • ---------- • ---------- • ---------- ■■ ER-clinic Day ☀️🚨 ■■ • ---------- • ---------- • ---------- • ---------- • ---------- • ---------- • ---------- • ---------- • ---------- ■■ ER GENERAL-DAY-🚨☀️ ■■ • رنا اكرم احمد (01122182132) • رنيم حاتم رفيق بسيسو (01144758373) • مها حسين السيد (01012349071) • محمد خالد محمد (01008204601) • كارين باسم صومائيل (01274209975) • Mostafa Ismail (01022400525) • هديل هشام منصور الوشاحي (01227221344) • سعيد السيد محمد السيد محمد سابق (01203394950) • هديل نادي محند (01033032220) ■■ ER GENERAL-NIGHT-🚨🌙 ■■ • أحمد زيدان (01110524147) • شدو محمد شلتوت (1550336384) • مي طارق نهاد (01287477488) • عمرو وائل سرور (01023140340) • الاء الحداد (01033882560) • محمد عمرو محمد عبدالباقي (01151653320) • احمد ايهاب محمد عواد (01032298339) • Rawan Elessawy (01010983040) • ---------- ■■ ER PT-DAY-🚨☀️ ■■ • مصطفى محمد علي محمد بدر (01150245681) • حنان النبوى محمد (01067888751) • عمرو عبدالغفار حمزة (01014246636) • Youssef elsemary (01126286820) • مريم السيد أحمد خيرالله (01099882992) • منار عواد عبدالعال عواد (01001915861) • أعناب طارق عوض (01146334179) • رؤى أحمد عبدالحميد البليهي (01021284862) • ---------- ■■ ER PT-NIGHT-🚨🌙 ■■ • احمد حسين أحمد (01001877491) • بلال جودة (01066199644) • عمر حسن محمد حسن حجازي (01019701020) • نورهان محمد (0112 826 8287) • احمدنوید قیومی (01104573242) • مصطفى عبد الراضى صديق (01226696153) • منه الله هشام السيد (01002996214) • محمد خالد محمد (01008204601) • عمر حسن محمد حسن حجازي (01019701020) ■■ ER TRIAGE-DAY-🚨☀️ ■■ • عبدالمسيح مكرم (01203267885) • ---------- • ---------- • ---------- • ---------- • ---------- • ---------- • ---------- • ---------- ■■ ER TRIAGE-NIGHT-🚨🌙 ■■ • شيماء رمضان سعد (01021468731) • ---------- • ---------- • ---------- • ---------- • ---------- • ---------- • ---------- • ---------- ■■ ER WARD-DAY-🚨☀️ ■■ • ملك محمد فؤاد (01001721072) • بلال جودة (01066199644) • Marwan Ayman (01149894940) • أحمد زيدان (01110524147) • ريهام سعد عبدالرحمن (01124867574) • محمود محمد عبدالرحمن (01023283048) • ---------- • ---------- • ---------- ■■ ER WARD-NIGHT-🚨🌙 ■■ • محمد الجمل (01091463337) • احمد عزت الشيخ (01226872660) • يوسف طه السيد (01207620695) • سندس أحمد سيد (01156131096) • Mohamed Ahmed • عبدالله احمد (01020242571) • ---------- • ---------- • ---------- ■■ 🗡️LISTA ■■ • ---------- • ---------- • ---------- • ---------- • ---------- • ---------- • ---------- • ---------- • ---------- ■■ WARD-DAY-☀️ ■■ • ---------- • ---------- • ---------- • ---------- • ---------- • ---------- • ---------- • ---------- • ---------- ■■ WARD-NIGHT-🌙 ■■ • ---------- • ---------- • ---------- • ---------- • ---------- • ---------- • ---------- • ---------- • ---------- | C7: =HYPERLINK("#الجدول!A" & 35, "الجدول الأساسي") -> الجدول الأساسي
A8: 2026-02-07 السبت | B8: ="" & "■■ " & 'الجدول'!B1 & " ■■" & CHAR(10) & "• " & 'الجدول'!B45 & CHAR(10) & "• " & 'الجدول'!B46 & CHAR(10) & "• " & 'الجدول'!B47 & CHAR(10) & "• " & 'الجدول'!B48 & CHAR(10) & "• " & 'الجدول'!B49 & CHAR(10) & "• " & 'الجدول'!B50 & CHAR(10) & "• " & 'الجدول'!B51 & CHAR(10) & "• " & 'الجدول'!B52 & CHAR(10) & CHAR(10) & "■■ " & 'الجدول'!C1 & " ■■" & CHAR(10) & "• " & 'الجدول'!C45 & CHAR(10) & "• " & 'الجدول'!C46 & CHAR(10) & "• " & 'الجدول'!C47 & CHAR(10) & "• " & 'الجدول'!C48 & CHAR(10) & "• " & 'الجدول'!C49 & CHAR(10) & "• " & 'الجدول'!C50 & CHAR(10) & "• " & 'الجدول'!C51 & CHAR(10) & "• " & 'الجدول'!C52 & CHAR(10) & CHAR(10) & "■■ " & 'الجدول'!D1 & " ■■" & CHAR(10) & "• " & 'الجدول'!D45 & CHAR(10) & "• " & 'الجدول'!D46 & CHAR(10) & "• " & 'الجدول'!D47 & CHAR(10) & "• " & 'الجدول'!D48 & CHAR(10) & "• " & 'الجدول'!D49 & CHAR(10) & "• " & 'الجدول'!D50 & CHAR(10) & "• " & 'الجدول'!D51 & CHAR(10) & "• " & 'الجدول'!D52 & CHAR(10) & CHAR(10) & "■■ " & 'الجدول'!E1 & " ■■" & CHAR(10) & "• " & 'الجدول'!E45 & CHAR(10) & "• " & 'الجدول'!E46 & CHAR(10) & "• " & 'الجدول'!E47 & CHAR(10) & "• " & 'الجدول'!E48 & CHAR(10) & "• " & 'الجدول'!E49 & CHAR(10) & "• " & 'الجدول'!E50 & CHAR(10) & "• " & 'الجدول'!E51 & CHAR(10) & "• " & 'الجدول'!E52 & CHAR(10) & CHAR(10) & "■■ " & 'الجدول'!F1 & " ■■" & CHAR(10) & "• " & 'الجدول'!F45 & CHAR(10) & "• " & 'الجدول'!F46 & CHAR(10) & "• " & 'الجدول'!F47 & CHAR(10) & "• " & 'الجدول'!F48 & CHAR(10) & "• " & 'الجدول'!F49 & CHAR(10) & "• " & 'الجدول'!F50 & CHAR(10) & "• " & 'الجدول'!F51 & CHAR(10) & "• " & 'الجدول'!F52 & CHAR(10) & CHAR(10) & "■■ " & 'الجدول'!G1 & " ■■" & CHAR(10) & "• " & 'الجدول'!G45 & CHAR(10) & "• " & 'الجدول'!G46 & CHAR(10) & "• " & 'الجدول'!G47 & CHAR(10) & "• " & 'الجدول'!G48 & CHAR(10) & "• " & 'الجدول'!G49 & CHAR(10) & "• " & 'الجدول'!G50 & CHAR(10) & "• " & 'الجدول'!G51 & CHAR(10) & "• " & 'الجدول'!G52 & CHAR(10) & CHAR(10) & "■■ " & 'الجدول'!H1 & " ■■" & CHAR(10) & "• " & 'الجدول'!H45 & CHAR(10) & "• " & 'الجدول'!H46 & CHAR(10) & "• " & 'الجدول'!H47 & CHAR(10) & "• " & 'الجدول'!H48 & CHAR(10) & "• " & 'الجدول'!H49 & CHAR(10) & "• " & 'الجدول'!H50 & CHAR(10) & "• " & 'الجدول'!H51 & CHAR(10) & "• " & 'الجدول'!H52 & CHAR(10) & CHAR(10) & "■■ " & 'الجدول'!I1 & " ■■" & CHAR(10) & "• " & 'الجدول'!I45 & CHAR(10) & "• " & 'الجدول'!I46 & CHAR(10) & "• " & 'الجدول'!I47 & CHAR(10) & "• " & 'الجدول'!I48 & CHAR(10) & "• " & 'الجدول'!I49 & CHAR(10) & "• " & 'الجدول'!I50 & CHAR(10) & "• " & 'الجدول'!I51 & CHAR(10) & "• " & 'الجدول'!I52 & CHAR(10) & CHAR(10) & "■■ " & 'الجدول'!J1 & " ■■" & CHAR(10) & "• " & 'الجدول'!J45 & CHAR(10) & "• " & 'الجدول'!J46 & CHAR(10) & "• " & 'الجدول'!J47 & CHAR(10) & "• " & 'الجدول'!J48 & CHAR(10) & "• " & 'الجدول'!J49 & CHAR(10) & "• " & 'الجدول'!J50 & CHAR(10) & "• " & 'الجدول'!J51 & CHAR(10) & "• " & 'الجدول'!J52 & CHAR(10) & CHAR(10) & "■■ " & 'الجدول'!K1 & " ■■" & CHAR(10) & "• " & 'الجدول'!K45 & CHAR(10) & "• " & 'الجدول'!K46 & CHAR(10) & "• " & 'الجدول'!K47 & CHAR(10) & "• " & 'الجدول'!K48 & CHAR(10) & "• " & 'الجدول'!K49 & CHAR(10) & "• " & 'الجدول'!K50 & CHAR(10) & "• " & 'الجدول'!K51 & CHAR(10) & "• " & 'الجدول'!K52 & CHAR(10) & CHAR(10) & "■■ " & 'الجدول'!L1 & " ■■" & CHAR(10) & "• " & 'الجدول'!L45 & CHAR(10) & "• " & 'الجدول'!L46 & CHAR(10) & "• " & 'الجدول'!L47 & CHAR(10) & "• " & 'الجدول'!L48 & CHAR(10) & "• " & 'الجدول'!L49 & CHAR(10) & "• " & 'الجدول'!L50 & CHAR(10) & "• " & 'الجدول'!L51 & CHAR(10) & "• " & 'الجدول'!L52 & CHAR(10) & CHAR(10) & "■■ " & 'الجدول'!M1 & " ■■" & CHAR(10) & "• " & 'الجدول'!M45 & CHAR(10) & "• " & 'الجدول'!M46 & CHAR(10) & "• " & 'الجدول'!M47 & CHAR(10) & "• " & 'الجدول'!M48 & CHAR(10) & "• " & 'الجدول'!M49 & CHAR(10) & "• " & 'الجدول'!M50 & CHAR(10) & "• " & 'الجدول'!M51 & CHAR(10) & "• " & 'الجدول'!M52 & CHAR(10) & CHAR(10) & "■■ " & 'الجدول'!N1 & " ■■" & CHAR(10) & "• " & 'الجدول'!N45 & CHAR(10) & "• " & 'الجدول'!N46 & CHAR(10) & "• " & 'الجدول'!N47 & CHAR(10) & "• " & 'الجدول'!N48 & CHAR(10) & "• " & 'الجدول'!N49 & CHAR(10) & "• " & 'الجدول'!N50 & CHAR(10) & "• " & 'الجدول'!N51 & CHAR(10) & "• " & 'الجدول'!N52 & CHAR(10) & CHAR(10) & "■■ " & 'الجدول'!O1 & " ■■" & CHAR(10) & "• " & 'الجدول'!O45 & CHAR(10) & "• " & 'الجدول'!O46 & CHAR(10) & "• " & 'الجدول'!O47 & CHAR(10) & "• " & 'الجدول'!O48 & CHAR(10) & "• " & 'الجدول'!O49 & CHAR(10) & "• " & 'الجدول'!O50 & CHAR(10) & "• " & 'الجدول'!O51 & CHAR(10) & "• " & 'الجدول'!O52 & CHAR(10) & CHAR(10) -> ■■ ER ADMISSION-NIGHT-🚨🌙 ■■ • ---------- • ---------- • ---------- • ---------- • ---------- • ---------- • ---------- • ---------- ■■ ER ADMISSIONS -DAY-🚨☀️ ■■ • ---------- • ---------- • ---------- • ---------- • ---------- • ---------- • ---------- • ---------- ■■ ER-clinic Day ☀️🚨 ■■ • ---------- • ---------- • ---------- • ---------- • ---------- • ---------- • ---------- • ---------- ■■ ER GENERAL-DAY-🚨☀️ ■■ • ---------- • ---------- • ---------- • ---------- • ---------- • ---------- • ---------- • ---------- ■■ ER GENERAL-NIGHT-🚨🌙 ■■ • ---------- • ---------- • ---------- • ---------- • ---------- • ---------- • ---------- • ---------- ■■ ER PT-DAY-🚨☀️ ■■ • ---------- • ---------- • ---------- • ---------- • ---------- • ---------- • ---------- • ---------- ■■ ER PT-NIGHT-🚨🌙 ■■ • ---------- • ---------- • ---------- • ---------- • ---------- • ---------- • ---------- • ---------- ■■ ER TRIAGE-DAY-🚨☀️ ■■ • ---------- • ---------- • ---------- • ---------- • ---------- • ---------- • ---------- • ---------- ■■ ER TRIAGE-NIGHT-🚨🌙 ■■ • ---------- • ---------- • ---------- • ---------- • ---------- • ---------- • ---------- • ---------- ■■ ER WARD-DAY-🚨☀️ ■■ • ---------- • ---------- • ---------- • ---------- • ---------- • ---------- • ---------- • ---------- ■■ ER WARD-NIGHT-🚨🌙 ■■ • ---------- • ---------- • ---------- • ---------- • ---------- • ---------- • ---------- • ---------- ■■ 🗡️LISTA ■■ • محمد عمرو محمد عبدالباقي (01151653320) • سلمى أبوالعلا (01124166114) • يوسف طه السيد (01207620695) • ---------- • ---------- • ---------- • ---------- • ---------- ■■ WARD-DAY-☀️ ■■ • منار عواد عبدالعال عواد (01001915861) • رؤى أحمد عبدالحميد البليهي (01021284862) • شيماء رمضان سعد (01021468731) • رنا اكرم احمد (01122182132) • احمد حسين أحمد (01001877491) • سعيد السيد محمد السيد محمد سابق (01203394950) • محمد خالد محمد (01008204601) • هديل نادي محند (01033032220) ■■ WARD-NIGHT-🌙 ■■ • احمد ايهاب محمد عواد (01032298339) • ملك محمد فؤاد (01001721072) • احمد ناصر (01553479200) • شدو محمد شلتوت (1550336384) • عمر محمد سيد (01000688544) • ---------- • ---------- • ---------- | C8: =HYPERLINK("#الجدول!A" & 44, "الجدول الأساسي") -> الجدول الأساسي
