Workbook

Sheet الجدول
B1: ER ADMISSION-NIGHT-🚨🌙 | C1: ER ADMISSIONS -DAY-🚨☀️ | D1: ER GENERAL-DAY-🚨☀️ | E1: ER GENERAL-NIGHT-🚨🌙 | F1: ER PT-DAY-🚨☀️ | G1: ER PT-NIGHT-🚨🌙 | H1: ER TRIAGE-DAY-🚨☀️ | I1: ER TRIAGE-NIGHT-🚨🌙 | J1: ER WARD-DAY-🚨☀️ | K1: ER WARD-NIGHT-🚨🌙 | L1: 🗡️LISTA | M1: WARD-DAY-☀️ | N1: WARD-NIGHT-🌙
A2: 2026-01-10 السبت | B2: ---------- | C2: ---------- | D2: ---------- | E2: ---------- | F2: ---------- | G2: ---------- | H2: ---------- | I2: ---------- | J2: ---------- | K2: ---------- | L2: هديل هشام منصور الوشاحي (01227221344) | M2: Sara Refaat (01220039613) | N2: يوسف عاطف رزق الله (01148183647) | O2: =HYPERLINK("#مجمع!B" & 1, "ورديات اليوم مجمعة") -> ورديات اليوم مجمعة
B3: ---------- | C3: ---------- | D3: ---------- | E3: ---------- | F3: ---------- | G3: ---------- | H3: ---------- | I3: ---------- | J3: ---------- | K3: ---------- | L3: دانه طارق (01012809042) | M3: عمرو عبدالغفار حمزة (01014246636) | N3: نورهان محمد (0112 826 8287)
B4: ---------- | C4: ---------- | D4: ---------- | E4: ---------- | F4: ---------- | G4: ---------- | H4: ---------- | I4: ---------- | J4: ---------- | K4: ---------- | L4: احمد حسين أحمد (01001877491) | M4: رؤى أحمد عبدالحميد البليهي (01021284862) | N4: احمد ايهاب محمد عواد (01032298339)
B5: ---------- | C5: ---------- | D5: ---------- | E5: ---------- | F5: ---------- | G5: ---------- | H5: ---------- | I5: ---------- | J5: ---------- | K5: ---------- | L5: ---------- | M5: محمد محمود ابراهيم (01112057358) | N5: ----------
B6: ---------- | C6: ---------- | D6: ---------- | E6: ---------- | F6: ---------- | G6: ---------- | H6: ---------- | I6: ---------- | J6: ---------- | K6: ---------- | L6: ---------- | M6: مينا رومانى عبده (01212866642) | N6: ----------
A7: 2026-01-11 الأحد | B7: Ziad said mohamed (01028577876) | C7: Sara Refaat (01220039613) | D7: حنان النبوى محمد (01067888751) | E7: مي طارق نهاد (01287477488) | F7: مينا رومانى عبده (01212866642) | G7: احمد حسين أحمد (01001877491) | H7: روان ياسر سليم (01005005160) | I7: عمرو عبدالغفار حمزة (01014246636) | J7: Alaa mahmoud El haddad (01033882560) | K7: محمد احمد بسام الجمل (01091463337) | L7: ---------- | M7: ---------- | N7: ---------- | O7: =HYPERLINK("#مجمع!B" & 2, "ورديات اليوم مجمعة") -> ورديات اليوم مجمعة
B8: ---------- | C8: ---------- | D8: هديل نادي محند (01033032220) | E8: شدو محمد شلتوت (1550336384) | F8: عبدالمسيح مكرم (01203267885) | G8: سندس أحمد سيد (01156131096) | H8: ---------- | I8: ---------- | J8: منة السيد عبد الباقي (01274588193) | K8: عبدالله احمد (01020242571) | L8: ---------- | M8: ---------- | N8: ----------
B9: ---------- | C9: ---------- | D9: محمود عبد المحسن إبراهيم (01062086612) | E9: كارين باسم صومائيل (01274209975) | F9: رؤى أحمد عبدالحميد البليهي (01021284862) | G9: احمد ناصر (01553479200) | H9: ---------- | I9: ---------- | J9: سعيد السيد محمد السيد محمد سابق (01203394950) | K9: احمد عزت الشيخ (01226872660) | L9: ---------- | M9: ---------- | N9: ----------
B10: ---------- | C10: ---------- | D10: منه الله هشام السيد (01002996214) | E10: زينة أشرف حسين (01067196820) | F10: منار عواد عبدالعال عواد (01001915861) | G10: يوسف طه السيد (01207620695) | H10: ---------- | I10: ---------- | J10: مصطفى عبد الراضى صديق (01226696153) | K10: تقى عماد حسني (01119716276) | L10: ---------- | M10: ---------- | N10: ----------
B11: ---------- | C11: ---------- | D11: سلمى أبوالعلا (01124166114) | E11: شهاب احمد حلمي (01055979002) | F11: مصطفى محمد علي محمد بدر (01150245681) | G11: احمد حسام الدين صلاح (01065567736) | H11: ---------- | I11: ---------- | J11: عمرو وائل سرور (01023140340) | K11: مصطفى عبد الراضى صديق (01226696153) | L11: ---------- | M11: ---------- | N11: ----------
B12: ---------- | C12: ---------- | D12: بلال جودة (01066199644) | E12: محمد عمرو محمد عبدالباقي (01151653320) | F12: استيفن مدحت منير (01200226122) | G12: Mostafa Ismail (01022400525) | H12: ---------- | I12: ---------- | J12: كارين روماني راشد (01102663062) | K12: عمرو وائل سرور (01023140340) | L12: ---------- | M12: ---------- | N12: ----------
B13: ---------- | C13: ---------- | D13: بلال أحمد (01066883767) | E13: Marwan Ayman (01149894940) | F13: مها حسين السيد (01012349071) | G13: عمر محمد سيد (01000688544) | H13: ---------- | I13: ---------- | J13: ---------- | K13: ---------- | L13: ---------- | M13: ---------- | N13: ----------
B14: ---------- | C14: ---------- | D14: Youssef elsemary (01126286820) | E14: محمد محمود ابراهيم (01112057358) | F14: هديل هشام منصور الوشاحي (01227221344) | G14: نورهان محمد (0112 826 8287) | H14: ---------- | I14: ---------- | J14: ---------- | K14: ---------- | L14: ---------- | M14: ---------- | N14: ----------
B15: ---------- | C15: ---------- | D15: عمر حسن محمد حسن حجازي (01019701020) | E15: أحمد زيدان (01110524147) | F15: منار احمد سعيد (01092708033) | G15: احمدنوید قیومی (01104573242) | H15: ---------- | I15: ---------- | J15: ---------- | K15: ---------- | L15: ---------- | M15: ---------- | N15: ----------
B16: ---------- | C16: ---------- | D16: شيماء رمضان سعد (01021468731) | E16: ---------- | F16: ---------- | G16: ---------- | H16: ---------- | I16: ---------- | J16: ---------- | K16: ---------- | L16: ---------- | M16: ---------- | N16: ----------
A17: 2026-01-12 الاثنين | B17: ---------- | C17: ---------- | D17: ---------- | E17: ---------- | F17: ---------- | G17: ---------- | H17: ---------- | I17: ---------- | J17: ---------- | K17: ---------- | L17: ---------- | M17: مي خالد ابوزيد (01023578224) | N17: عمرو وائل سرور (01023140340) | O17: =HYPERLINK("#مجمع!B" & 3, "ورديات اليوم مجمعة") -> ورديات اليوم مجمعة
B18: ---------- | C18: ---------- | D18: ---------- | E18: ---------- | F18: ---------- | G18: ---------- | H18: ---------- | I18: ---------- | J18: ---------- | K18: ---------- | L18: ---------- | M18: عبدالمسيح مكرم (01203267885) | N18: مريم السيد أحمد خيرالله (01099882992)
B19: ---------- | C19: ---------- | D19: ---------- | E19: ---------- | F19: ---------- | G19: ---------- | H19: ---------- | I19: ---------- | J19: ---------- | K19: ---------- | L19: ---------- | M19: أحمد رجب محمد (01273127265) | N19: نورهان محمد (0112 826 8287)
B20: ---------- | C20: ---------- | D20: ---------- | E20: ---------- | F20: ---------- | G20: ---------- | H20: ---------- | I20: ---------- | J20: ---------- | K20: ---------- | L20: ---------- | M20: مصطفى محمد علي محمد بدر (01150245681) | N20: شهاب احمد حلمي (01055979002)
B21: ---------- | C21: ---------- | D21: ---------- | E21: ---------- | F21: ---------- | G21: ---------- | H21: ---------- | I21: ---------- | J21: ---------- | K21: ---------- | L21: ---------- | M21: دانه طارق (01012809042) | N21: تقى عماد حسني (01119716276)
B22: ---------- | C22: ---------- | D22: ---------- | E22: ---------- | F22: ---------- | G22: ---------- | H22: ---------- | I22: ---------- | J22: ---------- | K22: ---------- | L22: ---------- | M22: محمد خالد محمد (01008204601) | N22: ----------
B23: ---------- | C23: ---------- | D23: ---------- | E23: ---------- | F23: ---------- | G23: ---------- | H23: ---------- | I23: ---------- | J23: ---------- | K23: ---------- | L23: ---------- | M23: كارين روماني راشد (01102663062) | N23: ----------
B24: ---------- | C24: ---------- | D24: ---------- | E24: ---------- | F24: ---------- | G24: ---------- | H24: ---------- | I24: ---------- | J24: ---------- | K24: ---------- | L24: ---------- | M24: بلال أحمد (01066883767) | N24: ----------
A25: 2026-01-13 الثلاثاء | B25: ---------- | C25: ---------- | D25: ---------- | E25: ---------- | F25: ---------- | G25: ---------- | H25: ---------- | I25: ---------- | J25: ---------- | K25: ---------- | L25: يوسف عاطف رزق الله (01148183647) | M25: محمود عبد المحسن إبراهيم (01062086612) | N25: محمد احمد بسام الجمل (01091463337) | O25: =HYPERLINK("#مجمع!B" & 4, "ورديات اليوم مجمعة") -> ورديات اليوم مجمعة
B26: ---------- | C26: ---------- | D26: ---------- | E26: ---------- | F26: ---------- | G26: ---------- | H26: ---------- | I26: ---------- | J26: ---------- | K26: ---------- | L26: محمد خالد محمد (01008204601) | M26: استيفن مدحت منير (01200226122) | N26: كارين باسم صومائيل (01274209975)
B27: ---------- | C27: ---------- | D27: ---------- | E27: ---------- | F27: ---------- | G27: ---------- | H27: ---------- | I27: ---------- | J27: ---------- | K27: ---------- | L27: سعيد السيد محمد السيد محمد سابق (01203394950) | M27: أعناب طارق عوض (01146334179) | N27: مي طارق نهاد (01287477488)
B28: ---------- | C28: ---------- | D28: ---------- | E28: ---------- | F28: ---------- | G28: ---------- | H28: ---------- | I28: ---------- | J28: ---------- | K28: ---------- | L28: ---------- | M28: احمد حسام الدين صلاح (01065567736) | N28: احمد عزت الشيخ (01226872660)
B29: ---------- | C29: ---------- | D29: ---------- | E29: ---------- | F29: ---------- | G29: ---------- | H29: ---------- | I29: ---------- | J29: ---------- | K29: ---------- | L29: ---------- | M29: منار عواد عبدالعال عواد (01001915861) | N29: ----------
B30: ---------- | C30: ---------- | D30: ---------- | E30: ---------- | F30: ---------- | G30: ---------- | H30: ---------- | I30: ---------- | J30: ---------- | K30: ---------- | L30: ---------- | M30: احمدنوید قیومی (01104573242) | N30: ----------
A31: 2026-01-14 الأربعاء | B31: ---------- | C31: ---------- | D31: ---------- | E31: ---------- | F31: ---------- | G31: ---------- | H31: ---------- | I31: ---------- | J31: ---------- | K31: ---------- | L31: ---------- | M31: رنيم حاتم رفيق بسيسو (01144758373) | N31: محمد احمد بسام الجمل (01091463337) | O31: =HYPERLINK("#مجمع!B" & 5, "ورديات اليوم مجمعة") -> ورديات اليوم مجمعة
B32: ---------- | C32: ---------- | D32: ---------- | E32: ---------- | F32: ---------- | G32: ---------- | H32: ---------- | I32: ---------- | J32: ---------- | K32: ---------- | L32: ---------- | M32: Ziad said mohamed (01028577876) | N32: ملك محمد فؤاد (01001721072)
B33: ---------- | C33: ---------- | D33: ---------- | E33: ---------- | F33: ---------- | G33: ---------- | H33: ---------- | I33: ---------- | J33: ---------- | K33: ---------- | L33: ---------- | M33: سلمى أبوالعلا (01124166114) | N33: سندس أحمد سيد (01156131096)
B34: ---------- | C34: ---------- | D34: ---------- | E34: ---------- | F34: ---------- | G34: ---------- | H34: ---------- | I34: ---------- | J34: ---------- | K34: ---------- | L34: ---------- | M34: منار احمد سعيد (01092708033) | N34: احمد عزت الشيخ (01226872660)
B35: ---------- | C35: ---------- | D35: ---------- | E35: ---------- | F35: ---------- | G35: ---------- | H35: ---------- | I35: ---------- | J35: ---------- | K35: ---------- | L35: ---------- | M35: بلال جودة (01066199644) | N35: ----------
B36: ---------- | C36: ---------- | D36: ---------- | E36: ---------- | F36: ---------- | G36: ---------- | H36: ---------- | I36: ---------- | J36: ---------- | K36: ---------- | L36: ---------- | M36: عمر حسن محمد حسن حجازي (01019701020) | N36: ----------
A37: 2026-01-15 الخميس | B37: ---------- | C37: ---------- | D37: ---------- | E37: ---------- | F37: ---------- | G37: ---------- | H37: ---------- | I37: ---------- | J37: ---------- | K37: ---------- | L37: ---------- | M37: مها حسين السيد (01012349071) | N37: تقى عماد حسني (01119716276) | O37: =HYPERLINK("#مجمع!B" & 6, "ورديات اليوم مجمعة") -> ورديات اليوم مجمعة
B38: ---------- | C38: ---------- | D38: ---------- | E38: ---------- | F38: ---------- | G38: ---------- | H38: ---------- | I38: ---------- | J38: ---------- | K38: ---------- | L38: ---------- | M38: محمد خالد محمد (01008204601) | N38: رنا اكرم احمد (01122182132)
B39: ---------- | C39: ---------- | D39: ---------- | E39: ---------- | F39: ---------- | G39: ---------- | H39: ---------- | I39: ---------- | J39: ---------- | K39: ---------- | L39: ---------- | M39: زينة أشرف حسين (01067196820) | N39: Marwan Ayman (01149894940)
B40: ---------- | C40: ---------- | D40: ---------- | E40: ---------- | F40: ---------- | G40: ---------- | H40: ---------- | I40: ---------- | J40: ---------- | K40: ---------- | L40: ---------- | M40: مي خالد ابوزيد (01023578224) | N40: ----------
...

Sheet مجمع
A1: اليوم | B1: الورديات مجمعة
A2: 2026-01-10 السبت | B2: ="" & "■■ " & 'الجدول'!B1 & " ■■" & CHAR(10) & "• " & 'الجدول'!B2 & CHAR(10) & "• " & 'الجدول'!B3 & CHAR(10) & "• " & 'الجدول'!B4 & CHAR(10) & "• " & 'الجدول'!B5 & CHAR(10) & "• " & 'الجدول'!B6 & CHAR(10) & CHAR(10) & "■■ " & 'الجدول'!C1 & " ■■" & CHAR(10) & "• " & 'الجدول'!C2 & CHAR(10) & "• " & 'الجدول'!C3 & CHAR(10) & "• " & 'الجدول'!C4 & CHAR(10) & "• " & 'الجدول'!C5 & CHAR(10) & "• " & 'الجدول'!C6 & CHAR(10) & CHAR(10) & "■■ " & 'الجدول'!D1 & " ■■" & CHAR(10) & "• " & 'الجدول'!D2 & CHAR(10) & "• " & 'الجدول'!D3 & CHAR(10) & "• " & 'الجدول'!D4 & CHAR(10) & "• " & 'الجدول'!D5 & CHAR(10) & "• " & 'الجدول'!D6 & CHAR(10) & CHAR(10) & "■■ " & 'الجدول'!E1 & " ■■" & CHAR(10) & "• " & 'الجدول'!E2 & CHAR(10) & "• " & 'الجدول'!E3 & CHAR(10) & "• " & 'الجدول'!E4 & CHAR(10) & "• " & 'الجدول'!E5 & CHAR(10) & "• " & 'الجدول'!E6 & CHAR(10) & CHAR(10) & "■■ " & 'الجدول'!F1 & " ■■" & CHAR(10) & "• " & 'الجدول'!F2 & CHAR(10) & "• " & 'الجدول'!F3 & CHAR(10) & "• " & 'الجدول'!F4 & CHAR(10) & "• " & 'الجدول'!F5 & CHAR(10) & "• " & 'الجدول'!F6 & CHAR(10) & CHAR(10) & "■■ " & 'الجدول'!G1 & " ■■" & CHAR(10) & "• " & 'الجدول'!G2 & CHAR(10) & "• " & 'الجدول'!G3 & CHAR(10) & "• " & 'الجدول'!G4 & CHAR(10) & "• " & 'الجدول'!G5 & CHAR(10) & "• " & 'الجدول'!G6 & CHAR(10) & CHAR(10) & "■■ " & 'الجدول'!H1 & " ■■" & CHAR(10) & "• " & 'الجدول'!H2 & CHAR(10) & "• " & 'الجدول'!H3 & CHAR(10) & "• " & 'الجدول'!H4 & CHAR(10) & "• " & 'الجدول'!H5 & CHAR(10) & "• " & 'الجدول'!H6 & CHAR(10) & CHAR(10) & "■■ " & 'الجدول'!I1 & " ■■" & CHAR(10) & "• " & 'الجدول'!I2 & CHAR(10) & "• " & 'الجدول'!I3 & CHAR(10) & "• " & 'الجدول'!I4 & CHAR(10) & "• " & 'الجدول'!I5 & CHAR(10) & "• " & 'الجدول'!I6 & CHAR(10) & CHAR(10) & "■■ " & 'الجدول'!J1 & " ■■" & CHAR(10) & "• " & 'الجدول'!J2 & CHAR(10) & "• " & 'الجدول'!J3 & CHAR(10) & "• " & 'الجدول'!J4 & CHAR(10) & "• " & 'الجدول'!J5 & CHAR(10) & "• " & 'الجدول'!J6 & CHAR(10) & CHAR(10) & "■■ " & 'الجدول'!K1 & " ■■" & CHAR(10) & "• " & 'الجدول'!K2 & CHAR(10) & "• " & 'الجدول'!K3 & CHAR(10) & "• " & 'الجدول'!K4 & CHAR(10) & "• " & 'الجدول'!K5 & CHAR(10) & "• " & 'الجدول'!K6 & CHAR(10) & CHAR(10) & "■■ " & 'الجدول'!L1 & " ■■" & CHAR(10) & "• " & 'الجدول'!L2 & CHAR(10) & "• " & 'الجدول'!L3 & CHAR(10) & "• " & 'الجدول'!L4 & CHAR(10) & "• " & 'الجدول'!L5 & CHAR(10) & "• " & 'الجدول'!L6 & CHAR(10) & CHAR(10) & "■■ " & 'الجدول'!M1 & " ■■" & CHAR(10) & "• " & 'الجدول'!M2 & CHAR(10) & "• " & 'الجدول'!M3 & CHAR(10) & "• " & 'الجدول'!M4 & CHAR(10) & "• " & 'الجدول'!M5 & CHAR(10) & "• " & 'الجدول'!M6 & CHAR(10) & CHAR(10) & "■■ " & 'الجدول'!N1 & " ■■" & CHAR(10) & "• " & 'الجدول'!N2 & CHAR(10) & "• " & 'الجدول'!N3 & CHAR(10) & "• " & 'الجدول'!N4 & CHAR(10) & "• " & 'الجدول'!N5 & CHAR(10) & "• " & 'الجدول'!N6 & CHAR(10) & CHAR(10) -> ■■ ER ADMISSION-NIGHT-🚨🌙 ■■ • ---------- • ---------- • ---------- • ---------- • ---------- ■■ ER ADMISSIONS -DAY-🚨☀️ ■■ • ---------- • ---------- • ---------- • ---------- • ---------- ■■ ER GENERAL-DAY-🚨☀️ ■■ • ---------- • ---------- • ---------- • ---------- • ---------- ■■ ER GENERAL-NIGHT-🚨🌙 ■■ • ---------- • ---------- • ---------- • ---------- • ---------- ■■ ER PT-DAY-🚨☀️ ■■ • ---------- • ---------- • ---------- • ---------- • ---------- ■■ ER PT-NIGHT-🚨🌙 ■■ • ---------- • ---------- • ---------- • ---------- • ---------- ■■ ER TRIAGE-DAY-🚨☀️ ■■ • ---------- • ---------- • ---------- • ---------- • ---------- ■■ ER TRIAGE-NIGHT-🚨🌙 ■■ • ---------- • ---------- • ---------- • ---------- • ---------- ■■ ER WARD-DAY-🚨☀️ ■■ • ---------- • ---------- • ---------- • ---------- • ---------- ■■ ER WARD-NIGHT-🚨🌙 ■■ • ---------- • ---------- • ---------- • ---------- • ---------- ■■ 🗡️LISTA ■■ • هديل هشام منصور الوشاحي (01227221344) • دانه طارق (01012809042) • احمد حسين أحمد (01001877491) • ---------- • ---------- ■■ WARD-DAY-☀️ ■■ • Sara Refaat (01220039613) • عمرو عبدالغفار حمزة (01014246636) • رؤى أحمد عبدالحميد البليهي (01021284862) • محمد محمود ابراهيم (01112057358) • مينا رومانى عبده (01212866642) ■■ WARD-NIGHT-🌙 ■■ • يوسف عاطف رزق الله (01148183647) • نورهان محمد (0112 826 8287) • احمد ايهاب محمد عواد (01032298339) • ---------- • ---------- | C2: =HYPERLINK("#الجدول!A" & 1, "الجدول الأساسي") -> الجدول الأساسي
A3: 2026-01-11 الأحد | B3: ="" & "■■ " & 'الجدول'!B1 & " ■■" & CHAR(10) & "• " & 'الجدول'!B7 & CHAR(10) & "• " & 'الجدول'!B8 & CHAR(10) & "• " & 'الجدول'!B9 & CHAR(10) & "• " & 'الجدول'!B10 & CHAR(10) & "• " & 'الجدول'!B11 & CHAR(10) & "• " & 'الجدول'!B12 & CHAR(10) & "• " & 'الجدول'!B13 & CHAR(10) & "• " & 'الجدول'!B14 & CHAR(10) & "• " & 'الجدول'!B15 & CHAR(10) & "• " & 'الجدول'!B16 & CHAR(10) & CHAR(10) & "■■ " & 'الجدول'!C1 & " ■■" & CHAR(10) & "• " & 'الجدول'!C7 & CHAR(10) & "• " & 'الجدول'!C8 & CHAR(10) & "• " & 'الجدول'!C9 & CHAR(10) & "• " & 'الجدول'!C10 & CHAR(10) & "• " & 'الجدول'!C11 & CHAR(10) & "• " & 'الجدول'!C12 & CHAR(10) & "• " & 'الجدول'!C13 & CHAR(10) & "• " & 'الجدول'!C14 & CHAR(10) & "• " & 'الجدول'!C15 & CHAR(10) & "• " & 'الجدول'!C16 & CHAR(10) & CHAR(10) & "■■ " & 'الجدول'!D1 & " ■■" & CHAR(10) & "• " & 'الجدول'!D7 & CHAR(10) & "• " & 'الجدول'!D8 & CHAR(10) & "• " & 'الجدول'!D9 & CHAR(10) & "• " & 'الجدول'!D10 & CHAR(10) & "• " & 'الجدول'!D11 & CHAR(10) & "• " & 'الجدول'!D12 & CHAR(10) & "• " & 'الجدول'!D13 & CHAR(10) & "• " & 'الجدول'!D14 & CHAR(10) & "• " & 'الجدول'!D15 & CHAR(10) & "• " & 'الجدول'!D16 & CHAR(10) & CHAR(10) & "■■ " & 'الجدول'!E1 & " ■■" & CHAR(10) & "• " & 'الجدول'!E7 & CHAR(10) & "• " & 'الجدول'!E8 & CHAR(10) & "• " & 'الجدول'!E9 & CHAR(10) & "• " & 'الجدول'!E10 & CHAR(10) & "• " & 'الجدول'!E11 & CHAR(10) & "• " & 'الجدول'!E12 & CHAR(10) & "• " & 'الجدول'!E13 & CHAR(10) & "• " & 'الجدول'!E14 & CHAR(10) & "• " & 'الجدول'!E15 & CHAR(10) & "• " & 'الجدول'!E16 & CHAR(10) & CHAR(10) & "■■ " & 'الجدول'!F1 & " ■■" & CHAR(10) & "• " & 'الجدول'!F7 & CHAR(10) & "• " & 'الجدول'!F8 & CHAR(10) & "• " & 'الجدول'!F9 & CHAR(10) & "• " & 'الجدول'!F10 & CHAR(10) & "• " & 'الجدول'!F11 & CHAR(10) & "• " & 'الجدول'!F12 & CHAR(10) & "• " & 'الجدول'!F13 & CHAR(10) & "• " & 'الجدول'!F14 & CHAR(10) & "• " & 'الجدول'!F15 & CHAR(10) & "• " & 'الجدول'!F16 & CHAR(10) & CHAR(10) & "■■ " & 'الجدول'!G1 & " ■■" & CHAR(10) & "• " & 'الجدول'!G7 & CHAR(10) & "• " & 'الجدول'!G8 & CHAR(10) & "• " & 'الجدول'!G9 & CHAR(10) & "• " & 'الجدول'!G10 & CHAR(10) & "• " & 'الجدول'!G11 & CHAR(10) & "• " & 'الجدول'!G12 & CHAR(10) & "• " & 'الجدول'!G13 & CHAR(10) & "• " & 'الجدول'!G14 & CHAR(10) & "• " & 'الجدول'!G15 & CHAR(10) & "• " & 'الجدول'!G16 & CHAR(10) & CHAR(10) & "■■ " & 'الجدول'!H1 & " ■■" & CHAR(10) & "• " & 'الجدول'!H7 & CHAR(10) & "• " & 'الجدول'!H8 & CHAR(10) & "• " & 'الجدول'!H9 & CHAR(10) & "• " & 'الجدول'!H10 & CHAR(10) & "• " & 'الجدول'!H11 & CHAR(10) & "• " & 'الجدول'!H12 & CHAR(10) & "• " & 'الجدول'!H13 & CHAR(10) & "• " & 'الجدول'!H14 & CHAR(10) & "• " & 'الجدول'!H15 & CHAR(10) & "• " & 'الجدول'!H16 & CHAR(10) & CHAR(10) & "■■ " & 'الجدول'!I1 & " ■■" & CHAR(10) & "• " & 'الجدول'!I7 & CHAR(10) & "• " & 'الجدول'!I8 & CHAR(10) & "• " & 'الجدول'!I9 & CHAR(10) & "• " & 'الجدول'!I10 & CHAR(10) & "• " & 'الجدول'!I11 & CHAR(10) & "• " & 'الجدول'!I12 & CHAR(10) & "• " & 'الجدول'!I13 & CHAR(10) & "• " & 'الجدول'!I14 & CHAR(10) & "• " & 'الجدول'!I15 & CHAR(10) & "• " & 'الجدول'!I16 & CHAR(10) & CHAR(10) & "■■ " & 'الجدول'!J1 & " ■■" & CHAR(10) & "• " & 'الجدول'!J7 & CHAR(10) & "• " & 'الجدول'!J8 & CHAR(10) & "• " & 'الجدول'!J9 & CHAR(10) & "• " & 'الجدول'!J10 & CHAR(10) & "• " & 'الجدول'!J11 & CHAR(10) & "• " & 'الجدول'!J12 & CHAR(10) & "• " & 'الجدول'!J13 & CHAR(10) & "• " & 'الجدول'!J14 & CHAR(10) & "• " & 'الجدول'!J15 & CHAR(10) & "• " & 'الجدول'!J16 & CHAR(10) & CHAR(10) & "■■ " & 'الجدول'!K1 & " ■■" & CHAR(10) & "• " & 'الجدول'!K7 & CHAR(10) & "• " & 'الجدول'!K8 & CHAR(10) & "• " & 'الجدول'!K9 & CHAR(10) & "• " & 'الجدول'!K10 & CHAR(10) & "• " & 'الجدول'!K11 & CHAR(10) & "• " & 'الجدول'!K12 & CHAR(10) & "• " & 'الجدول'!K13 & CHAR(10) & "• " & 'الجدول'!K14 & CHAR(10) & "• " & 'الجدول'!K15 & CHAR(10) & "• " & 'الجدول'!K16 & CHAR(10) & CHAR(10) & "■■ " & 'الجدول'!L1 & " ■■" & CHAR(10) & "• " & 'الجدول'!L7 & CHAR(10) & "• " & 'الجدول'!L8 & CHAR(10) & "• " & 'الجدول'!L9 & CHAR(10) & "• " & 'الجدول'!L10 & CHAR(10) & "• " & 'الجدول'!L11 & CHAR(10) & "• " & 'الجدول'!L12 & CHAR(10) & "• " & 'الجدول'!L13 & CHAR(10) & "• " & 'الجدول'!L14 & CHAR(10) & "• " & 'الجدول'!L15 & CHAR(10) & "• " & 'الجدول'!L16 & CHAR(10) & CHAR(10) & "■■ " & 'الجدول'!M1 & " ■■" & CHAR(10) & "• " & 'الجدول'!M7 & CHAR(10) & "• " & 'الجدول'!M8 & CHAR(10) & "• " & 'الجدول'!M9 & CHAR(10) & "• " & 'الجدول'!M10 & CHAR(10) & "• " & 'الجدول'!M11 & CHAR(10) & "• " & 'الجدول'!M12 & CHAR(10) & "• " & 'الجدول'!M13 & CHAR(10) & "• " & 'الجدول'!M14 & CHAR(10) & "• " & 'الجدول'!M15 & CHAR(10) & "• " & 'الجدول'!M16 & CHAR(10) & CHAR(10) & "■■ " & 'الجدول'!N1 & " ■■" & CHAR(10) & "• " & 'الجدول'!N7 & CHAR(10) & "• " & 'الجدول'!N8 & CHAR(10) & "• " & 'الجدول'!N9 & CHAR(10) & "• " & 'الجدول'!N10 & CHAR(10) & "• " & 'الجدول'!N11 & CHAR(10) & "• " & 'الجدول'!N12 & CHAR(10) & "• " & 'الجدول'!N13 & CHAR(10) & "• " & 'الجدول'!N14 & CHAR(10) & "• " & 'الجدول'!N15 & CHAR(10) & "• " & 'الجدول'!N16 & CHAR(10) & CHAR(10) -> ■■ ER ADMISSION-NIGHT-🚨🌙 ■■ • Ziad said mohamed (01028577876) • ---------- • ---------- • ---------- • ---------- • ---------- • ---------- • ---------- • ---------- • ---------- ■■ ER ADMISSIONS -DAY-🚨☀️ ■■ • Sara Refaat (01220039613) • ---------- • ---------- • ---------- • ---------- • ---------- • ---------- • ---------- • ---------- • ---------- ■■ ER GENERAL-DAY-🚨☀️ ■■ • حنان النبوى محمد (01067888751) • هديل نادي محند (01033032220) • محمود عبد المحسن إبراهيم (01062086612) • منه الله هشام السيد (01002996214) • سلمى أبوالعلا (01124166114) • بلال جودة (01066199644) • بلال أحمد (01066883767) • Youssef elsemary (01126286820) • عمر حسن محمد حسن حجازي (01019701020) • شيماء رمضان سعد (01021468731) ■■ ER GENERAL-NIGHT-🚨🌙 ■■ • مي طارق نهاد (01287477488) • شدو محمد شلتوت (1550336384) • كارين باسم صومائيل (01274209975) • زينة أشرف حسين (01067196820) • شهاب احمد حلمي (01055979002) • محمد عمرو محمد عبدالباقي (01151653320) • Marwan Ayman (01149894940) • محمد محمود ابراهيم (01112057358) • أحمد زيدان (01110524147) • ---------- ■■ ER PT-DAY-🚨☀️ ■■ • مينا رومانى عبده (01212866642) • عبدالمسيح مكرم (01203267885) • رؤى أحمد عبدالحميد البليهي (01021284862) • منار عواد عبدالعال عواد (01001915861) • مصطفى محمد علي محمد بدر (01150245681) • استيفن مدحت منير (01200226122) • مها حسين السيد (01012349071) • هديل هشام منصور الوشاحي (01227221344) • منار احمد سعيد (01092708033) • ---------- ■■ ER PT-NIGHT-🚨🌙 ■■ • احمد حسين أحمد (01001877491) • سندس أحمد سيد (01156131096) • احمد ناصر (01553479200) • يوسف طه السيد (01207620695) • احمد حسام الدين صلاح (01065567736) • Mostafa Ismail (01022400525) • عمر محمد سيد (01000688544) • نورهان محمد (0112 826 8287) • احمدنوید قیومی (01104573242) • ---------- ■■ ER TRIAGE-DAY-🚨☀️ ■■ • روان ياسر سليم (01005005160) • ---------- • ---------- • ---------- • ---------- • ---------- • ---------- • ---------- • ---------- • ---------- ■■ ER TRIAGE-NIGHT-🚨🌙 ■■ • عمرو عبدالغفار حمزة (01014246636) • ---------- • ---------- • ---------- • ---------- • ---------- • ---------- • ---------- • ---------- • ---------- ■■ ER WARD-DAY-🚨☀️ ■■ • Alaa mahmoud El haddad (01033882560) • منة السيد عبد الباقي (01274588193) • سعيد السيد محمد السيد محمد سابق (01203394950) • مصطفى عبد الراضى صديق (01226696153) • عمرو وائل سرور (01023140340) • كارين روماني راشد (01102663062) • ---------- • ---------- • ---------- • ---------- ■■ ER WARD-NIGHT-🚨🌙 ■■ • محمد احمد بسام الجمل (01091463337) • عبدالله احمد (01020242571) • احمد عزت الشيخ (01226872660) • تقى عماد حسني (01119716276) • مصطفى عبد الراضى صديق (01226696153) • عمرو وائل سرور (01023140340) • ---------- • ---------- • ---------- • ---------- ■■ 🗡️LISTA ■■ • ---------- • ---------- • ---------- • ---------- • ---------- • ---------- • ---------- • ---------- • ---------- • ---------- ■■ WARD-DAY-☀️ ■■ • ---------- • ---------- • ---------- • ---------- • ---------- • ---------- • ---------- • ---------- • ---------- • ---------- ■■ WARD-NIGHT-🌙 ■■ • ---------- • ---------- • ---------- • ---------- • ---------- • ---------- • ---------- • ---------- • ---------- • ---------- | C3: =HYPERLINK("#الجدول!A" & 6, "الجدول الأساسي") -> الجدول الأساسي
A4: 2026-01-12 الاثنين | B4: ="" & "■■ " & 'الجدول'!B1 & " ■■" & CHAR(10) & "• " & 'الجدول'!B17 & CHAR(10) & "• " & 'الجدول'!B18 & CHAR(10) & "• " & 'الجدول'!B19 & CHAR(10) & "• " & 'الجدول'!B20 & CHAR(10) & "• " & 'الجدول'!B21 & CHAR(10) & "• " & 'الجدول'!B22 & CHAR(10) & "• " & 'الجدول'!B23 & CHAR(10) & "• " & 'الجدول'!B24 & CHAR(10) & CHAR(10) & "■■ " & 'الجدول'!C1 & " ■■" & CHAR(10) & "• " & 'الجدول'!C17 & CHAR(10) & "• " & 'الجدول'!C18 & CHAR(10) & "• " & 'الجدول'!C19 & CHAR(10) & "• " & 'الجدول'!C20 & CHAR(10) & "• " & 'الجدول'!C21 & CHAR(10) & "• " & 'الجدول'!C22 & CHAR(10) & "• " & 'الجدول'!C23 & CHAR(10) & "• " & 'الجدول'!C24 & CHAR(10) & CHAR(10) & "■■ " & 'الجدول'!D1 & " ■■" & CHAR(10) & "• " & 'الجدول'!D17 & CHAR(10) & "• " & 'الجدول'!D18 & CHAR(10) & "• " & 'الجدول'!D19 & CHAR(10) & "• " & 'الجدول'!D20 & CHAR(10) & "• " & 'الجدول'!D21 & CHAR(10) & "• " & 'الجدول'!D22 & CHAR(10) & "• " & 'الجدول'!D23 & CHAR(10) & "• " & 'الجدول'!D24 & CHAR(10) & CHAR(10) & "■■ " & 'الجدول'!E1 & " ■■" & CHAR(10) & "• " & 'الجدول'!E17 & CHAR(10) & "• " & 'الجدول'!E18 & CHAR(10) & "• " & 'الجدول'!E19 & CHAR(10) & "• " & 'الجدول'!E20 & CHAR(10) & "• " & 'الجدول'!E21 & CHAR(10) & "• " & 'الجدول'!E22 & CHAR(10) & "• " & 'الجدول'!E23 & CHAR(10) & "• " & 'الجدول'!E24 & CHAR(10) & CHAR(10) & "■■ " & 'الجدول'!F1 & " ■■" & CHAR(10) & "• " & 'الجدول'!F17 & CHAR(10) & "• " & 'الجدول'!F18 & CHAR(10) & "• " & 'الجدول'!F19 & CHAR(10) & "• " & 'الجدول'!F20 & CHAR(10) & "• " & 'الجدول'!F21 & CHAR(10) & "• " & 'الجدول'!F22 & CHAR(10) & "• " & 'الجدول'!F23 & CHAR(10) & "• " & 'الجدول'!F24 & CHAR(10) & CHAR(10) & "■■ " & 'الجدول'!G1 & " ■■" & CHAR(10) & "• " & 'الجدول'!G17 & CHAR(10) & "• " & 'الجدول'!G18 & CHAR(10) & "• " & 'الجدول'!G19 & CHAR(10) & "• " & 'الجدول'!G20 & CHAR(10) & "• " & 'الجدول'!G21 & CHAR(10) & "• " & 'الجدول'!G22 & CHAR(10) & "• " & 'الجدول'!G23 & CHAR(10) & "• " & 'الجدول'!G24 & CHAR(10) & CHAR(10) & "■■ " & 'الجدول'!H1 & " ■■" & CHAR(10) & "• " & 'الجدول'!H17 & CHAR(10) & "• " & 'الجدول'!H18 & CHAR(10) & "• " & 'الجدول'!H19 & CHAR(10) & "• " & 'الجدول'!H20 & CHAR(10) & "• " & 'الجدول'!H21 & CHAR(10) & "• " & 'الجدول'!H22 & CHAR(10) & "• " & 'الجدول'!H23 & CHAR(10) & "• " & 'الجدول'!H24 & CHAR(10) & CHAR(10) & "■■ " & 'الجدول'!I1 & " ■■" & CHAR(10) & "• " & 'الجدول'!I17 & CHAR(10) & "• " & 'الجدول'!I18 & CHAR(10) & "• " & 'الجدول'!I19 & CHAR(10) & "• " & 'الجدول'!I20 & CHAR(10) & "• " & 'الجدول'!I21 & CHAR(10) & "• " & 'الجدول'!I22 & CHAR(10) & "• " & 'الجدول'!I23 & CHAR(10) & "• " & 'الجدول'!I24 & CHAR(10) & CHAR(10) & "■■ " & 'الجدول'!J1 & " ■■" & CHAR(10) & "• " & 'الجدول'!J17 & CHAR(10) & "• " & 'الجدول'!J18 & CHAR(10) & "• " & 'الجدول'!J19 & CHAR(10) & "• " & 'الجدول'!J20 & CHAR(10) & "• " & 'الجدول'!J21 & CHAR(10) & "• " & 'الجدول'!J22 & CHAR(10) & "• " & 'الجدول'!J23 & CHAR(10) & "• " & 'الجدول'!J24 & CHAR(10) & CHAR(10) & "■■ " & 'الجدول'!K1 & " ■■" & CHAR(10) & "• " & 'الجدول'!K17 & CHAR(10) & "• " & 'الجدول'!K18 & CHAR(10) & "• " & 'الجدول'!K19 & CHAR(10) & "• " & 'الجدول'!K20 & CHAR(10) & "• " & 'الجدول'!K21 & CHAR(10) & "• " & 'الجدول'!K22 & CHAR(10) & "• " & 'الجدول'!K23 & CHAR(10) & "• " & 'الجدول'!K24 & CHAR(10) & CHAR(10) & "■■ " & 'الجدول'!L1 & " ■■" & CHAR(10) & "• " & 'الجدول'!L17 & CHAR(10) & "• " & 'الجدول'!L18 & CHAR(10) & "• " & 'الجدول'!L19 & CHAR(10) & "• " & 'الجدول'!L20 & CHAR(10) & "• " & 'الجدول'!L21 & CHAR(10) & "• " & 'الجدول'!L22 & CHAR(10) & "• " & 'الجدول'!L23 & CHAR(10) & "• " & 'الجدول'!L24 & CHAR(10) & CHAR(10) & "■■ " & 'الجدول'!M1 & " ■■" & CHAR(10) & "• " & 'الجدول'!M17 & CHAR(10) & "• " & 'الجدول'!M18 & CHAR(10) & "• " & 'الجدول'!M19 & CHAR(10) & "• " & 'الجدول'!M20 & CHAR(10) & "• " & 'الجدول'!M21 & CHAR(10) & "• " & 'الجدول'!M22 & CHAR(10) & "• " & 'الجدول'!M23 & CHAR(10) & "• " & 'الجدول'!M24 & CHAR(10) & CHAR(10) & "■■ " & 'الجدول'!N1 & " ■■" & CHAR(10) & "• " & 'الجدول'!N17 & CHAR(10) & "• " & 'الجدول'!N18 & CHAR(10) & "• " & 'الجدول'!N19 & CHAR(10) & "• " & 'الجدول'!N20 & CHAR(10) & "• " & 'الجدول'!N21 & CHAR(10) & "• " & 'الجدول'!N22 & CHAR(10) & "• " & 'الجدول'!N23 & CHAR(10) & "• " & 'الجدول'!N24 & CHAR(10) & CHAR(10) -> ■■ ER ADMISSION-NIGHT-🚨🌙 ■■ • ---------- • ---------- • ---------- • ---------- • ---------- • ---------- • ---------- • ---------- ■■ ER ADMISSIONS -DAY-🚨☀️ ■■ • ---------- • ---------- • ---------- • ---------- • ---------- • ---------- • ---------- • ---------- ■■ ER GENERAL-DAY-🚨☀️ ■■ • ---------- • ---------- • ---------- • ---------- • ---------- • ---------- • ---------- • ---------- ■■ ER GENERAL-NIGHT-🚨🌙 ■■ • ---------- • ---------- • ---------- • ---------- • ---------- • ---------- • ---------- • ---------- ■■ ER PT-DAY-🚨☀️ ■■ • ---------- • ---------- • ---------- • ---------- • ---------- • ---------- • ---------- • ---------- ■■ ER PT-NIGHT-🚨🌙 ■■ • ---------- • ---------- • ---------- • ---------- • ---------- • ---------- • ---------- • ---------- ■■ ER TRIAGE-DAY-🚨☀️ ■■ • ---------- • ---------- • ---------- • ---------- • ---------- • ---------- • ---------- • ---------- ■■ ER TRIAGE-NIGHT-🚨🌙 ■■ • ---------- • ---------- • ---------- • ---------- • ---------- • ---------- • ---------- • ---------- ■■ ER WARD-DAY-🚨☀️ ■■ • ---------- • ---------- • ---------- • ---------- • ---------- • ---------- • ---------- • ---------- ■■ ER WARD-NIGHT-🚨🌙 ■■ • ---------- • ---------- • ---------- • ---------- • ---------- • ---------- • ---------- • ---------- ■■ 🗡️LISTA ■■ • ---------- • ---------- • ---------- • ---------- • ---------- • ---------- • ---------- • ---------- ■■ WARD-DAY-☀️ ■■ • مي خالد ابوزيد (01023578224) • عبدالمسيح مكرم (01203267885) • أحمد رجب محمد (01273127265) • مصطفى محمد علي محمد بدر (01150245681) • دانه طارق (01012809042) • محمد خالد محمد (01008204601) • كارين روماني راشد (01102663062) • بلال أحمد (01066883767) ■■ WARD-NIGHT-🌙 ■■ • عمرو وائل سرور (01023140340) • مريم السيد أحمد خيرالله (01099882992) • نورهان محمد (0112 826 8287) • شهاب احمد حلمي (01055979002) • تقى عماد حسني (01119716276) • ---------- • ---------- • ---------- | C4: =HYPERLINK("#الجدول!A" & 16, "الجدول الأساسي") -> الجدول الأساسي
A5: 2026-01-13 الثلاثاء | B5: ="" & "■■ " & 'الجدول'!B1 & " ■■" & CHAR(10) & "• " & 'الجدول'!B25 & CHAR(10) & "• " & 'الجدول'!B26 & CHAR(10) & "• " & 'الجدول'!B27 & CHAR(10) & "• " & 'الجدول'!B28 & CHAR(10) & "• " & 'الجدول'!B29 & CHAR(10) & "• " & 'الجدول'!B30 & CHAR(10) & CHAR(10) & "■■ " & 'الجدول'!C1 & " ■■" & CHAR(10) & "• " & 'الجدول'!C25 & CHAR(10) & "• " & 'الجدول'!C26 & CHAR(10) & "• " & 'الجدول'!C27 & CHAR(10) & "• " & 'الجدول'!C28 & CHAR(10) & "• " & 'الجدول'!C29 & CHAR(10) & "• " & 'الجدول'!C30 & CHAR(10) & CHAR(10) & "■■ " & 'الجدول'!D1 & " ■■" & CHAR(10) & "• " & 'الجدول'!D25 & CHAR(10) & "• " & 'الجدول'!D26 & CHAR(10) & "• " & 'الجدول'!D27 & CHAR(10) & "• " & 'الجدول'!D28 & CHAR(10) & "• " & 'الجدول'!D29 & CHAR(10) & "• " & 'الجدول'!D30 & CHAR(10) & CHAR(10) & "■■ " & 'الجدول'!E1 & " ■■" & CHAR(10) & "• " & 'الجدول'!E25 & CHAR(10) & "• " & 'الجدول'!E26 & CHAR(10) & "• " & 'الجدول'!E27 & CHAR(10) & "• " & 'الجدول'!E28 & CHAR(10) & "• " & 'الجدول'!E29 & CHAR(10) & "• " & 'الجدول'!E30 & CHAR(10) & CHAR(10) & "■■ " & 'الجدول'!F1 & " ■■" & CHAR(10) & "• " & 'الجدول'!F25 & CHAR(10) & "• " & 'الجدول'!F26 & CHAR(10) & "• " & 'الجدول'!F27 & CHAR(10) & "• " & 'الجدول'!F28 & CHAR(10) & "• " & 'الجدول'!F29 & CHAR(10) & "• " & 'الجدول'!F30 & CHAR(10) & CHAR(10) & "■■ " & 'الجدول'!G1 & " ■■" & CHAR(10) & "• " & 'الجدول'!G25 & CHAR(10) & "• " & 'الجدول'!G26 & CHAR(10) & "• " & 'الجدول'!G27 & CHAR(10) & "• " & 'الجدول'!G28 & CHAR(10) & "• " & 'الجدول'!G29 & CHAR(10) & "• " & 'الجدول'!G30 & CHAR(10) & CHAR(10) & "■■ " & 'الجدول'!H1 & " ■■" & CHAR(10) & "• " & 'الجدول'!H25 & CHAR(10) & "• " & 'الجدول'!H26 & CHAR(10) & "• " & 'الجدول'!H27 & CHAR(10) & "• " & 'الجدول'!H28 & CHAR(10) & "• " & 'الجدول'!H29 & CHAR(10) & "• " & 'الجدول'!H30 & CHAR(10) & CHAR(10) & "■■ " & 'الجدول'!I1 & " ■■" & CHAR(10) & "• " & 'الجدول'!I25 & CHAR(10) & "• " & 'الجدول'!I26 & CHAR(10) & "• " & 'الجدول'!I27 & CHAR(10) & "• " & 'الجدول'!I28 & CHAR(10) & "• " & 'الجدول'!I29 & CHAR(10) & "• " & 'الجدول'!I30 & CHAR(10) & CHAR(10) & "■■ " & 'الجدول'!J1 & " ■■" & CHAR(10) & "• " & 'الجدول'!J25 & CHAR(10) & "• " & 'الجدول'!J26 & CHAR(10) & "• " & 'الجدول'!J27 & CHAR(10) & "• " & 'الجدول'!J28 & CHAR(10) & "• " & 'الجدول'!J29 & CHAR(10) & "• " & 'الجدول'!J30 & CHAR(10) & CHAR(10) & "■■ " & 'الجدول'!K1 & " ■■" & CHAR(10) & "• " & 'الجدول'!K25 & CHAR(10) & "• " & 'الجدول'!K26 & CHAR(10) & "• " & 'الجدول'!K27 & CHAR(10) & "• " & 'الجدول'!K28 & CHAR(10) & "• " & 'الجدول'!K29 & CHAR(10) & "• " & 'الجدول'!K30 & CHAR(10) & CHAR(10) & "■■ " & 'الجدول'!L1 & " ■■" & CHAR(10) & "• " & 'الجدول'!L25 & CHAR(10) & "• " & 'الجدول'!L26 & CHAR(10) & "• " & 'الجدول'!L27 & CHAR(10) & "• " & 'الجدول'!L28 & CHAR(10) & "• " & 'الجدول'!L29 & CHAR(10) & "• " & 'الجدول'!L30 & CHAR(10) & CHAR(10) & "■■ " & 'الجدول'!M1 & " ■■" & CHAR(10) & "• " & 'الجدول'!M25 & CHAR(10) & "• " & 'الجدول'!M26 & CHAR(10) & "• " & 'الجدول'!M27 & CHAR(10) & "• " & 'الجدول'!M28 & CHAR(10) & "• " & 'الجدول'!M29 & CHAR(10) & "• " & 'الجدول'!M30 & CHAR(10) & CHAR(10) & "■■ " & 'الجدول'!N1 & " ■■" & CHAR(10) & "• " & 'الجدول'!N25 & CHAR(10) & "• " & 'الجدول'!N26 & CHAR(10) & "• " & 'الجدول'!N27 & CHAR(10) & "• " & 'الجدول'!N28 & CHAR(10) & "• " & 'الجدول'!N29 & CHAR(10) & "• " & 'الجدول'!N30 & CHAR(10) & CHAR(10) -> ■■ ER ADMISSION-NIGHT-🚨🌙 ■■ • ---------- • ---------- • ---------- • ---------- • ---------- • ---------- ■■ ER ADMISSIONS -DAY-🚨☀️ ■■ • ---------- • ---------- • ---------- • ---------- • ---------- • ---------- ■■ ER GENERAL-DAY-🚨☀️ ■■ • ---------- • ---------- • ---------- • ---------- • ---------- • ---------- ■■ ER GENERAL-NIGHT-🚨🌙 ■■ • ---------- • ---------- • ---------- • ---------- • ---------- • ---------- ■■ ER PT-DAY-🚨☀️ ■■ • ---------- • ---------- • ---------- • ---------- • ---------- • ---------- ■■ ER PT-NIGHT-🚨🌙 ■■ • ---------- • ---------- • ---------- • ---------- • ---------- • ---------- ■■ ER TRIAGE-DAY-🚨☀️ ■■ • ---------- • ---------- • ---------- • ---------- • ---------- • ---------- ■■ ER TRIAGE-NIGHT-🚨🌙 ■■ • ---------- • ---------- • ---------- • ---------- • ---------- • ---------- ■■ ER WARD-DAY-🚨☀️ ■■ • ---------- • ---------- • ---------- • ---------- • ---------- • ---------- ■■ ER WARD-NIGHT-🚨🌙 ■■ • ---------- • ---------- • ---------- • ---------- • ---------- • ---------- ■■ 🗡️LISTA ■■ • يوسف عاطف رزق الله (01148183647) • محمد خالد محمد (01008204601) • سعيد السيد محمد السيد محمد سابق (01203394950) • ---------- • ---------- • ---------- ■■ WARD-DAY-☀️ ■■ • محمود عبد المحسن إبراهيم (01062086612) • استيفن مدحت منير (01200226122) • أعناب طارق عوض (01146334179) • احمد حسام الدين صلاح (01065567736) • منار عواد عبدالعال عواد (01001915861) • احمدنوید قیومی (01104573242) ■■ WARD-NIGHT-🌙 ■■ • محمد احمد بسام الجمل (01091463337) • كارين باسم صومائيل (01274209975) • مي طارق نهاد (01287477488) • احمد عزت الشيخ (01226872660) • ---------- • ---------- | C5: =HYPERLINK("#الجدول!A" & 24, "الجدول الأساسي") -> الجدول الأساسي
A6: 2026-01-14 الأربعاء | B6: ="" & "■■ " & 'الجدول'!B1 & " ■■" & CHAR(10) & "• " & 'الجدول'!B31 & CHAR(10) & "• " & 'الجدول'!B32 & CHAR(10) & "• " & 'الجدول'!B33 & CHAR(10) & "• " & 'الجدول'!B34 & CHAR(10) & "• " & 'الجدول'!B35 & CHAR(10) & "• " & 'الجدول'!B36 & CHAR(10) & CHAR(10) & "■■ " & 'الجدول'!C1 & " ■■" & CHAR(10) & "• " & 'الجدول'!C31 & CHAR(10) & "• " & 'الجدول'!C32 & CHAR(10) & "• " & 'الجدول'!C33 & CHAR(10) & "• " & 'الجدول'!C34 & CHAR(10) & "• " & 'الجدول'!C35 & CHAR(10) & "• " & 'الجدول'!C36 & CHAR(10) & CHAR(10) & "■■ " & 'الجدول'!D1 & " ■■" & CHAR(10) & "• " & 'الجدول'!D31 & CHAR(10) & "• " & 'الجدول'!D32 & CHAR(10) & "• " & 'الجدول'!D33 & CHAR(10) & "• " & 'الجدول'!D34 & CHAR(10) & "• " & 'الجدول'!D35 & CHAR(10) & "• " & 'الجدول'!D36 & CHAR(10) & CHAR(10) & "■■ " & 'الجدول'!E1 & " ■■" & CHAR(10) & "• " & 'الجدول'!E31 & CHAR(10) & "• " & 'الجدول'!E32 & CHAR(10) & "• " & 'الجدول'!E33 & CHAR(10) & "• " & 'الجدول'!E34 & CHAR(10) & "• " & 'الجدول'!E35 & CHAR(10) & "• " & 'الجدول'!E36 & CHAR(10) & CHAR(10) & "■■ " & 'الجدول'!F1 & " ■■" & CHAR(10) & "• " & 'الجدول'!F31 & CHAR(10) & "• " & 'الجدول'!F32 & CHAR(10) & "• " & 'الجدول'!F33 & CHAR(10) & "• " & 'الجدول'!F34 & CHAR(10) & "• " & 'الجدول'!F35 & CHAR(10) & "• " & 'الجدول'!F36 & CHAR(10) & CHAR(10) & "■■ " & 'الجدول'!G1 & " ■■" & CHAR(10) & "• " & 'الجدول'!G31 & CHAR(10) & "• " & 'الجدول'!G32 & CHAR(10) & "• " & 'الجدول'!G33 & CHAR(10) & "• " & 'الجدول'!G34 & CHAR(10) & "• " & 'الجدول'!G35 & CHAR(10) & "• " & 'الجدول'!G36 & CHAR(10) & CHAR(10) & "■■ " & 'الجدول'!H1 & " ■■" & CHAR(10) & "• " & 'الجدول'!H31 & CHAR(10) & "• " & 'الجدول'!H32 & CHAR(10) & "• " & 'الجدول'!H33 & CHAR(10) & "• " & 'الجدول'!H34 & CHAR(10) & "• " & 'الجدول'!H35 & CHAR(10) & "• " & 'الجدول'!H36 & CHAR(10) & CHAR(10) & "■■ " & 'الجدول'!I1 & " ■■" & CHAR(10) & "• " & 'الجدول'!I31 & CHAR(10) & "• " & 'الجدول'!I32 & CHAR(10) & "• " & 'الجدول'!I33 & CHAR(10) & "• " & 'الجدول'!I34 & CHAR(10) & "• " & 'الجدول'!I35 & CHAR(10) & "• " & 'الجدول'!I36 & CHAR(10) & CHAR(10) & "■■ " & 'الجدول'!J1 & " ■■" & CHAR(10) & "• " & 'الجدول'!J31 & CHAR(10) & "• " & 'الجدول'!J32 & CHAR(10) & "• " & 'الجدول'!J33 & CHAR(10) & "• " & 'الجدول'!J34 & CHAR(10) & "• " & 'الجدول'!J35 & CHAR(10) & "• " & 'الجدول'!J36 & CHAR(10) & CHAR(10) & "■■ " & 'الجدول'!K1 & " ■■" & CHAR(10) & "• " & 'الجدول'!K31 & CHAR(10) & "• " & 'الجدول'!K32 & CHAR(10) & "• " & 'الجدول'!K33 & CHAR(10) & "• " & 'الجدول'!K34 & CHAR(10) & "• " & 'الجدول'!K35 & CHAR(10) & "• " & 'الجدول'!K36 & CHAR(10) & CHAR(10) & "■■ " & 'الجدول'!L1 & " ■■" & CHAR(10) & "• " & 'الجدول'!L31 & CHAR(10) & "• " & 'الجدول'!L32 & CHAR(10) & "• " & 'الجدول'!L33 & CHAR(10) & "• " & 'الجدول'!L34 & CHAR(10) & "• " & 'الجدول'!L35 & CHAR(10) & "• " & 'الجدول'!L36 & CHAR(10) & CHAR(10) & "■■ " & 'الجدول'!M1 & " ■■" & CHAR(10) & "• " & 'الجدول'!M31 & CHAR(10) & "• " & 'الجدول'!M32 & CHAR(10) & "• " & 'الجدول'!M33 & CHAR(10) & "• " & 'الجدول'!M34 & CHAR(10) & "• " & 'الجدول'!M35 & CHAR(10) & "• " & 'الجدول'!M36 & CHAR(10) & CHAR(10) & "■■ " & 'الجدول'!N1 & " ■■" & CHAR(10) & "• " & 'الجدول'!N31 & CHAR(10) & "• " & 'الجدول'!N32 & CHAR(10) & "• " & 'الجدول'!N33 & CHAR(10) & "• " & 'الجدول'!N34 & CHAR(10) & "• " & 'الجدول'!N35 & CHAR(10) & "• " & 'الجدول'!N36 & CHAR(10) & CHAR(10) -> ■■ ER ADMISSION-NIGHT-🚨🌙 ■■ • ---------- • ---------- • ---------- • ---------- • ---------- • ---------- ■■ ER ADMISSIONS -DAY-🚨☀️ ■■ • ---------- • ---------- • ---------- • ---------- • ---------- • ---------- ■■ ER GENERAL-DAY-🚨☀️ ■■ • ---------- • ---------- • ---------- • ---------- • ---------- • ---------- ■■ ER GENERAL-NIGHT-🚨🌙 ■■ • ---------- • ---------- • ---------- • ---------- • ---------- • ---------- ■■ ER PT-DAY-🚨☀️ ■■ • ---------- • ---------- • ---------- • ---------- • ---------- • ---------- ■■ ER PT-NIGHT-🚨🌙 ■■ • ---------- • ---------- • ---------- • ---------- • ---------- • ---------- ■■ ER TRIAGE-DAY-🚨☀️ ■■ • ---------- • ---------- • ---------- • ---------- • ---------- • ---------- ■■ ER TRIAGE-NIGHT-🚨🌙 ■■ • ---------- • ---------- • ---------- • ---------- • ---------- • ---------- ■■ ER WARD-DAY-🚨☀️ ■■ • ---------- • ---------- • ---------- • ---------- • ---------- • ---------- ■■ ER WARD-NIGHT-🚨🌙 ■■ • ---------- • ---------- • ---------- • ---------- • ---------- • ---------- ■■ 🗡️LISTA ■■ • ---------- • ---------- • ---------- • ---------- • ---------- • ---------- ■■ WARD-DAY-☀️ ■■ • رنيم حاتم رفيق بسيسو (01144758373) • Ziad said mohamed (01028577876) • سلمى أبوالعلا (01124166114) • منار احمد سعيد (01092708033) • بلال جودة (01066199644) • عمر حسن محمد حسن حجازي (01019701020) ■■ WARD-NIGHT-🌙 ■■ • محمد احمد بسام الجمل (01091463337) • ملك محمد فؤاد (01001721072) • سندس أحمد سيد (01156131096) • احمد عزت الشيخ (01226872660) • ---------- • ---------- | C6: =HYPERLINK("#الجدول!A" & 30, "الجدول الأساسي") -> الجدول الأساسي
A7: 2026-01-15 الخميس | B7: ="" & "■■ " & 'الجدول'!B1 & " ■■" & CHAR(10) & "• " & 'الجدول'!B37 & CHAR(10) & "• " & 'الجدول'!B38 & CHAR(10) & "• " & 'الجدول'!B39 & CHAR(10) & "• " & 'الجدول'!B40 & CHAR(10) & "• " & 'الجدول'!B41 & CHAR(10) & CHAR(10) & "■■ " & 'الجدول'!C1 & " ■■" & CHAR(10) & "• " & 'الجدول'!C37 & CHAR(10) & "• " & 'الجدول'!C38 & CHAR(10) & "• " & 'الجدول'!C39 & CHAR(10) & "• " & 'الجدول'!C40 & CHAR(10) & "• " & 'الجدول'!C41 & CHAR(10) & CHAR(10) & "■■ " & 'الجدول'!D1 & " ■■" & CHAR(10) & "• " & 'الجدول'!D37 & CHAR(10) & "• " & 'الجدول'!D38 & CHAR(10) & "• " & 'الجدول'!D39 & CHAR(10) & "• " & 'الجدول'!D40 & CHAR(10) & "• " & 'الجدول'!D41 & CHAR(10) & CHAR(10) & "■■ " & 'الجدول'!E1 & " ■■" & CHAR(10) & "• " & 'الجدول'!E37 & CHAR(10) & "• " & 'الجدول'!E38 & CHAR(10) & "• " & 'الجدول'!E39 & CHAR(10) & "• " & 'الجدول'!E40 & CHAR(10) & "• " & 'الجدول'!E41 & CHAR(10) & CHAR(10) & "■■ " & 'الجدول'!F1 & " ■■" & CHAR(10) & "• " & 'الجدول'!F37 & CHAR(10) & "• " & 'الجدول'!F38 & CHAR(10) & "• " & 'الجدول'!F39 & CHAR(10) & "• " & 'الجدول'!F40 & CHAR(10) & "• " & 'الجدول'!F41 & CHAR(10) & CHAR(10) & "■■ " & 'الجدول'!G1 & " ■■" & CHAR(10) & "• " & 'الجدول'!G37 & CHAR(10) & "• " & 'الجدول'!G38 & CHAR(10) & "• " & 'الجدول'!G39 & CHAR(10) & "• " & 'الجدول'!G40 & CHAR(10) & "• " & 'الجدول'!G41 & CHAR(10) & CHAR(10) & "■■ " & 'الجدول'!H1 & " ■■" & CHAR(10) & "• " & 'الجدول'!H37 & CHAR(10) & "• " & 'الجدول'!H38 & CHAR(10) & "• " & 'الجدول'!H39 & CHAR(10) & "• " & 'الجدول'!H40 & CHAR(10) & "• " & 'الجدول'!H41 & CHAR(10) & CHAR(10) & "■■ " & 'الجدول'!I1 & " ■■" & CHAR(10) & "• " & 'الجدول'!I37 & CHAR(10) & "• " & 'الجدول'!I38 & CHAR(10) & "• " & 'الجدول'!I39 & CHAR(10) & "• " & 'الجدول'!I40 & CHAR(10) & "• " & 'الجدول'!I41 & CHAR(10) & CHAR(10) & "■■ " & 'الجدول'!J1 & " ■■" & CHAR(10) & "• " & 'الجدول'!J37 & CHAR(10) & "• " & 'الجدول'!J38 & CHAR(10) & "• " & 'الجدول'!J39 & CHAR(10) & "• " & 'الجدول'!J40 & CHAR(10) & "• " & 'الجدول'!J41 & CHAR(10) & CHAR(10) & "■■ " & 'الجدول'!K1 & " ■■" & CHAR(10) & "• " & 'الجدول'!K37 & CHAR(10) & "• " & 'الجدول'!K38 & CHAR(10) & "• " & 'الجدول'!K39 & CHAR(10) & "• " & 'الجدول'!K40 & CHAR(10) & "• " & 'الجدول'!K41 & CHAR(10) & CHAR(10) & "■■ " & 'الجدول'!L1 & " ■■" & CHAR(10) & "• " & 'الجدول'!L37 & CHAR(10) & "• " & 'الجدول'!L38 & CHAR(10) & "• " & 'الجدول'!L39 & CHAR(10) & "• " & 'الجدول'!L40 & CHAR(10) & "• " & 'الجدول'!L41 & CHAR(10) & CHAR(10) & "■■ " & 'الجدول'!M1 & " ■■" & CHAR(10) & "• " & 'الجدول'!M37 & CHAR(10) & "• " & 'الجدول'!M38 & CHAR(10) & "• " & 'الجدول'!M39 & CHAR(10) & "• " & 'الجدول'!M40 & CHAR(10) & "• " & 'الجدول'!M41 & CHAR(10) & CHAR(10) & "■■ " & 'الجدول'!N1 & " ■■" & CHAR(10) & "• " & 'الجدول'!N37 & CHAR(10) & "• " & 'الجدول'!N38 & CHAR(10) & "• " & 'الجدول'!N39 & CHAR(10) & "• " & 'الجدول'!N40 & CHAR(10) & "• " & 'الجدول'!N41 & CHAR(10) & CHAR(10) -> ■■ ER ADMISSION-NIGHT-🚨🌙 ■■ • ---------- • ---------- • ---------- • ---------- • ---------- ■■ ER ADMISSIONS -DAY-🚨☀️ ■■ • ---------- • ---------- • ---------- • ---------- • ---------- ■■ ER GENERAL-DAY-🚨☀️ ■■ • ---------- • ---------- • ---------- • ---------- • ---------- ■■ ER GENERAL-NIGHT-🚨🌙 ■■ • ---------- • ---------- • ---------- • ---------- • ---------- ■■ ER PT-DAY-🚨☀️ ■■ • ---------- • ---------- • ---------- • ---------- • ---------- ■■ ER PT-NIGHT-🚨🌙 ■■ • ---------- • ---------- • ---------- • ---------- • ---------- ■■ ER TRIAGE-DAY-🚨☀️ ■■ • ---------- • ---------- • ---------- • ---------- • ---------- ■■ ER TRIAGE-NIGHT-🚨🌙 ■■ • ---------- • ---------- • ---------- • ---------- • ---------- ■■ ER WARD-DAY-🚨☀️ ■■ • ---------- • ---------- • ---------- • ---------- • ---------- ■■ ER WARD-NIGHT-🚨🌙 ■■ • ---------- • ---------- • ---------- • ---------- • ---------- ■■ 🗡️LISTA ■■ • ---------- • ---------- • ---------- • ---------- • ---------- ■■ WARD-DAY-☀️ ■■ • مها حسين السيد (01012349071) • محمد خالد محمد (01008204601) • زينة أشرف حسين (01067196820) • مي خالد ابوزيد (01023578224) • عمرو عبدالغفار حمزة (01014246636) ■■ WARD-NIGHT-🌙 ■■ • تقى عماد حسني (01119716276) • رنا اكرم احمد (01122182132) • Marwan Ayman (01149894940) • ---------- • ---------- | C7: =HYPERLINK("#الجدول!A" & 36, "الجدول الأساسي") -> الجدول الأساسي
A8: 2026-01-16 الجمعة | B8: ="" & "■■ " & 'الجدول'!B1 & " ■■" & CHAR(10) & "• " & 'الجدول'!B42 & CHAR(10) & "• " & 'الجدول'!B43 & CHAR(10) & "• " & 'الجدول'!B44 & CHAR(10) & "• " & 'الجدول'!B45 & CHAR(10) & CHAR(10) & "■■ " & 'الجدول'!C1 & " ■■" & CHAR(10) & "• " & 'الجدول'!C42 & CHAR(10) & "• " & 'الجدول'!C43 & CHAR(10) & "• " & 'الجدول'!C44 & CHAR(10) & "• " & 'الجدول'!C45 & CHAR(10) & CHAR(10) & "■■ " & 'الجدول'!D1 & " ■■" & CHAR(10) & "• " & 'الجدول'!D42 & CHAR(10) & "• " & 'الجدول'!D43 & CHAR(10) & "• " & 'الجدول'!D44 & CHAR(10) & "• " & 'الجدول'!D45 & CHAR(10) & CHAR(10) & "■■ " & 'الجدول'!E1 & " ■■" & CHAR(10) & "• " & 'الجدول'!E42 & CHAR(10) & "• " & 'الجدول'!E43 & CHAR(10) & "• " & 'الجدول'!E44 & CHAR(10) & "• " & 'الجدول'!E45 & CHAR(10) & CHAR(10) & "■■ " & 'الجدول'!F1 & " ■■" & CHAR(10) & "• " & 'الجدول'!F42 & CHAR(10) & "• " & 'الجدول'!F43 & CHAR(10) & "• " & 'الجدول'!F44 & CHAR(10) & "• " & 'الجدول'!F45 & CHAR(10) & CHAR(10) & "■■ " & 'الجدول'!G1 & " ■■" & CHAR(10) & "• " & 'الجدول'!G42 & CHAR(10) & "• " & 'الجدول'!G43 & CHAR(10) & "• " & 'الجدول'!G44 & CHAR(10) & "• " & 'الجدول'!G45 & CHAR(10) & CHAR(10) & "■■ " & 'الجدول'!H1 & " ■■" & CHAR(10) & "• " & 'الجدول'!H42 & CHAR(10) & "• " & 'الجدول'!H43 & CHAR(10) & "• " & 'الجدول'!H44 & CHAR(10) & "• " & 'الجدول'!H45 & CHAR(10) & CHAR(10) & "■■ " & 'الجدول'!I1 & " ■■" & CHAR(10) & "• " & 'الجدول'!I42 & CHAR(10) & "• " & 'الجدول'!I43 & CHAR(10) & "• " & 'الجدول'!I44 & CHAR(10) & "• " & 'الجدول'!I45 & CHAR(10) & CHAR(10) & "■■ " & 'الجدول'!J1 & " ■■" & CHAR(10) & "• " & 'الجدول'!J42 & CHAR(10) & "• " & 'الجدول'!J43 & CHAR(10) & "• " & 'الجدول'!J44 & CHAR(10) & "• " & 'الجدول'!J45 & CHAR(10) & CHAR(10) & "■■ " & 'الجدول'!K1 & " ■■" & CHAR(10) & "• " & 'الجدول'!K42 & CHAR(10) & "• " & 'الجدول'!K43 & CHAR(10) & "• " & 'الجدول'!K44 & CHAR(10) & "• " & 'الجدول'!K45 & CHAR(10) & CHAR(10) & "■■ " & 'الجدول'!L1 & " ■■" & CHAR(10) & "• " & 'الجدول'!L42 & CHAR(10) & "• " & 'الجدول'!L43 & CHAR(10) & "• " & 'الجدول'!L44 & CHAR(10) & "• " & 'الجدول'!L45 & CHAR(10) & CHAR(10) & "■■ " & 'الجدول'!M1 & " ■■" & CHAR(10) & "• " & 'الجدول'!M42 & CHAR(10) & "• " & 'الجدول'!M43 & CHAR(10) & "• " & 'الجدول'!M44 & CHAR(10) & "• " & 'الجدول'!M45 & CHAR(10) & CHAR(10) & "■■ " & 'الجدول'!N1 & " ■■" & CHAR(10) & "• " & 'الجدول'!N42 & CHAR(10) & "• " & 'الجدول'!N43 & CHAR(10) & "• " & 'الجدول'!N44 & CHAR(10) & "• " & 'الجدول'!N45 & CHAR(10) & CHAR(10) -> ■■ ER ADMISSION-NIGHT-🚨🌙 ■■ • ---------- • ---------- • ---------- • ---------- ■■ ER ADMISSIONS -DAY-🚨☀️ ■■ • ---------- • ---------- • ---------- • ---------- ■■ ER GENERAL-DAY-🚨☀️ ■■ • ---------- • ---------- • ---------- • ---------- ■■ ER GENERAL-NIGHT-🚨🌙 ■■ • ---------- • ---------- • ---------- • ---------- ■■ ER PT-DAY-🚨☀️ ■■ • ---------- • ---------- • ---------- • ---------- ■■ ER PT-NIGHT-🚨🌙 ■■ • ---------- • ---------- • ---------- • ---------- ■■ ER TRIAGE-DAY-🚨☀️ ■■ • ---------- • ---------- • ---------- • ---------- ■■ ER TRIAGE-NIGHT-🚨🌙 ■■ • ---------- • ---------- • ---------- • ---------- ■■ ER WARD-DAY-🚨☀️ ■■ • ---------- • ---------- • ---------- • ---------- ■■ ER WARD-NIGHT-🚨🌙 ■■ • ---------- • ---------- • ---------- • ---------- ■■ 🗡️LISTA ■■ • ---------- • ---------- • ---------- • ---------- ■■ WARD-DAY-☀️ ■■ • أحمد زيدان (01110524147) • ريهام سعد عبدالرحمن (01124867574) • Alaa mahmoud El haddad (01033882560) • Mostafa Ismail (01022400525) ■■ WARD-NIGHT-🌙 ■■ • عبدالله احمد (01020242571) • احمد عزت الشيخ (01226872660) • احمدنوید قیومی (01104573242) • | C8: =HYPERLINK("#الجدول!A" & 41, "الجدول الأساسي") -> الجدول الأساسي
A9: 2026-01-17 السبت | B9: ="" & "■■ " & 'الجدول'!B1 & " ■■" & CHAR(10) & "• " & 'الجدول'!B46 & CHAR(10) & "• " & 'الجدول'!B47 & CHAR(10) & "• " & 'الجدول'!B48 & CHAR(10) & "• " & 'الجدول'!B49 & CHAR(10) & "• " & 'الجدول'!B50 & CHAR(10) & CHAR(10) & "■■ " & 'الجدول'!C1 & " ■■" & CHAR(10) & "• " & 'الجدول'!C46 & CHAR(10) & "• " & 'الجدول'!C47 & CHAR(10) & "• " & 'الجدول'!C48 & CHAR(10) & "• " & 'الجدول'!C49 & CHAR(10) & "• " & 'الجدول'!C50 & CHAR(10) & CHAR(10) & "■■ " & 'الجدول'!D1 & " ■■" & CHAR(10) & "• " & 'الجدول'!D46 & CHAR(10) & "• " & 'الجدول'!D47 & CHAR(10) & "• " & 'الجدول'!D48 & CHAR(10) & "• " & 'الجدول'!D49 & CHAR(10) & "• " & 'الجدول'!D50 & CHAR(10) & CHAR(10) & "■■ " & 'الجدول'!E1 & " ■■" & CHAR(10) & "• " & 'الجدول'!E46 & CHAR(10) & "• " & 'الجدول'!E47 & CHAR(10) & "• " & 'الجدول'!E48 & CHAR(10) & "• " & 'الجدول'!E49 & CHAR(10) & "• " & 'الجدول'!E50 & CHAR(10) & CHAR(10) & "■■ " & 'الجدول'!F1 & " ■■" & CHAR(10) & "• " & 'الجدول'!F46 & CHAR(10) & "• " & 'الجدول'!F47 & CHAR(10) & "• " & 'الجدول'!F48 & CHAR(10) & "• " & 'الجدول'!F49 & CHAR(10) & "• " & 'الجدول'!F50 & CHAR(10) & CHAR(10) & "■■ " & 'الجدول'!G1 & " ■■" & CHAR(10) & "• " & 'الجدول'!G46 & CHAR(10) & "• " & 'الجدول'!G47 & CHAR(10) & "• " & 'الجدول'!G48 & CHAR(10) & "• " & 'الجدول'!G49 & CHAR(10) & "• " & 'الجدول'!G50 & CHAR(10) & CHAR(10) & "■■ " & 'الجدول'!H1 & " ■■" & CHAR(10) & "• " & 'الجدول'!H46 & CHAR(10) & "• " & 'الجدول'!H47 & CHAR(10) & "• " & 'الجدول'!H48 & CHAR(10) & "• " & 'الجدول'!H49 & CHAR(10) & "• " & 'الجدول'!H50 & CHAR(10) & CHAR(10) & "■■ " & 'الجدول'!I1 & " ■■" & CHAR(10) & "• " & 'الجدول'!I46 & CHAR(10) & "• " & 'الجدول'!I47 & CHAR(10) & "• " & 'الجدول'!I48 & CHAR(10) & "• " & 'الجدول'!I49 & CHAR(10) & "• " & 'الجدول'!I50 & CHAR(10) & CHAR(10) & "■■ " & 'الجدول'!J1 & " ■■" & CHAR(10) & "• " & 'الجدول'!J46 & CHAR(10) & "• " & 'الجدول'!J47 & CHAR(10) & "• " & 'الجدول'!J48 & CHAR(10) & "• " & 'الجدول'!J49 & CHAR(10) & "• " & 'الجدول'!J50 & CHAR(10) & CHAR(10) & "■■ " & 'الجدول'!K1 & " ■■" & CHAR(10) & "• " & 'الجدول'!K46 & CHAR(10) & "• " & 'الجدول'!K47 & CHAR(10) & "• " & 'الجدول'!K48 & CHAR(10) & "• " & 'الجدول'!K49 & CHAR(10) & "• " & 'الجدول'!K50 & CHAR(10) & CHAR(10) & "■■ " & 'الجدول'!L1 & " ■■" & CHAR(10) & "• " & 'الجدول'!L46 & CHAR(10) & "• " & 'الجدول'!L47 & CHAR(10) & "• " & 'الجدول'!L48 & CHAR(10) & "• " & 'الجدول'!L49 & CHAR(10) & "• " & 'الجدول'!L50 & CHAR(10) & CHAR(10) & "■■ " & 'الجدول'!M1 & " ■■" & CHAR(10) & "• " & 'الجدول'!M46 & CHAR(10) & "• " & 'الجدول'!M47 & CHAR(10) & "• " & 'الجدول'!M48 & CHAR(10) & "• " & 'الجدول'!M49 & CHAR(10) & "• " & 'الجدول'!M50 & CHAR(10) & CHAR(10) & "■■ " & 'الجدول'!N1 & " ■■" & CHAR(10) & "• " & 'الجدول'!N46 & CHAR(10) & "• " & 'الجدول'!N47 & CHAR(10) & "• " & 'الجدول'!N48 & CHAR(10) & "• " & 'الجدول'!N49 & CHAR(10) & "• " & 'الجدول'!N50 & CHAR(10) & CHAR(10) -> ■■ ER ADMISSION-NIGHT-🚨🌙 ■■ • ---------- • ---------- • ---------- • ---------- • ---------- ■■ ER ADMISSIONS -DAY-🚨☀️ ■■ • ---------- • ---------- • ---------- • ---------- • ---------- ■■ ER GENERAL-DAY-🚨☀️ ■■ • ---------- • ---------- • ---------- • ---------- • ---------- ■■ ER GENERAL-NIGHT-🚨🌙 ■■ • ---------- • ---------- • ---------- • ---------- • ---------- ■■ ER PT-DAY-🚨☀️ ■■ • ---------- • ---------- • ---------- • ---------- • ---------- ■■ ER PT-NIGHT-🚨🌙 ■■ • ---------- • ---------- • ---------- • ---------- • ---------- ■■ ER TRIAGE-DAY-🚨☀️ ■■ • ---------- • ---------- • ---------- • ---------- • ---------- ■■ ER TRIAGE-NIGHT-🚨🌙 ■■ • ---------- • ---------- • ---------- • ---------- • ---------- ■■ ER WARD-DAY-🚨☀️ ■■ • ---------- • ---------- • ---------- • ---------- • ---------- ■■ ER WARD-NIGHT-🚨🌙 ■■ • ---------- • ---------- • ---------- • ---------- • ---------- ■■ 🗡️LISTA ■■ • منار عواد عبدالعال عواد (01001915861) • شدو محمد شلتوت (1550336384) • حنان النبوى محمد (01067888751) • ---------- • ---------- ■■ WARD-DAY-☀️ ■■ • محمد محمود ابراهيم (01112057358) • رؤى أحمد عبدالحميد البليهي (01021284862) • منه الله هشام السيد (01002996214) • احمدنوید قیومی (01104573242) • دانه طارق (01012809042) ■■ WARD-NIGHT-🌙 ■■ • كارين باسم صومائيل (01274209975) • احمد حسام الدين صلاح (01065567736) • احمد ايهاب محمد عواد (01032298339) • ---------- • ---------- | C9: =HYPERLINK("#الجدول!A" & 45, "الجدول الأساسي") -> الجدول الأساسي
